Workbook

Sheet Produtos
D1: Lançamentos, Custos, Vendas e DRE
A5: Data | B5: Projeto | C5: Consumo | J5: Custos | P5: Markup | Q5: 1.5 | R5: Realidade | T5: Valor Vendido | U5: % de Lucro ou Prejuízo
P6: Venda
C7: Impressora | D7: Filamento | E7: Filamento (g) | F7: Tempo | G7: Trabalho | H7: Insumos | I7: Embalagem | J7: Filamento | K7: Eletricidade | L7: Depreciação | M7: Trabalho | N7: Subtotal | O7: Valor Final | P7: Valor Sugerido | Q7: Marketplace | R7: Valor ECC | S7: Valor Mín.
A8: 46056 | B8: Porta Velas | C8: A1 Combo | D8: National3D PLA High Speed | E8: 174 | F8: 0.37152778 | G8: 0 | H8: 0 | I8: 0 | J8: =IFERROR(E8/1000*VLOOKUP(D8,Filamentos!A$2:I$96,9,FALSE),"") -> 17.4 | K8: =IFERROR(F8*24*VLOOKUP(C8,Impressoras!A$2:G$100,6,FALSE)*Outros!$B$2,"") -> 1.15025 | L8: =IFERROR(F8*24*VLOOKUP(C8,Impressoras!A$2:G$100,7,FALSE),"") -> 5.1500794 | M8: =IFERROR(G8*24*Outros!$B$3,"") -> 0 | N8: =IFERROR(SUM(J8:M8),"") -> 23.700329 | O8: =IFERROR(N8*(1+Outros!$B$4/100),"") -> 26.070362 | P8: =IFERROR(O8*Q$5,"") -> 39.105544 | Q8: =IFERROR(P8/(1-Outros!$B$6-Outros!$B$7)+Outros!$B$8,"") -> 52.881929 | R8: 60 | S8: 40 | U8: =IF(OR(T8="",T8=0),"",(T8-O8)/O8)
A9: 46057 | B9: Leonardo | C9: A1 Combo | D9: National3D PLA High Speed | E9: 193 | F9: 0.29166667 | G9: 0.0625 | H9: 35 | I9: 0 | J9: =IFERROR(E9/1000*VLOOKUP(D9,Filamentos!A$2:I$96,9,FALSE),"") -> 19.3 | K9: =IFERROR(F9*24*VLOOKUP(C9,Impressoras!A$2:G$100,6,FALSE)*Outros!$B$2,"") -> 0.903 | L9: =IFERROR(F9*24*VLOOKUP(C9,Impressoras!A$2:G$100,7,FALSE),"") -> 4.043053 | M9: =IFERROR(G9*24*Outros!$B$3,"") -> 15 | N9: =IFERROR(SUM(J9:M9),"") -> 39.246053 | O9: =IFERROR(N9*(1+Outros!$B$4/100),"") -> 43.170658 | P9: =IFERROR(O9*Q$5,"") -> 64.755987 | Q9: =IFERROR(P9/(1-Outros!$B$6-Outros!$B$7)+Outros!$B$8,"") -> 84.944984 | R9: 195 | S9: 150 | T9: 195 | U9: =IF(OR(T9="",T9=0),"",(T9-O9)/O9) -> 3.5169568
A10: 46065 | B10: Fabiano Base | C10: A1 Combo | D10: National3D PLA High Speed | E10: 27.05 | F10: 0.072916667 | G10: 0.020833333 | H10: 0 | I10: 0 | J10: =IFERROR(E10/1000*VLOOKUP(D10,Filamentos!A$2:I$96,9,FALSE),"") -> 2.705 | K10: =IFERROR(F10*24*VLOOKUP(C10,Impressoras!A$2:G$100,6,FALSE)*Outros!$B$2,"") -> 0.22575 | L10: =IFERROR(F10*24*VLOOKUP(C10,Impressoras!A$2:G$100,7,FALSE),"") -> 1.0107632 | M10: =IFERROR(G10*24*Outros!$B$3,"") -> 5 | N10: =IFERROR(SUM(J10:M10),"") -> 8.9415132 | O10: =IFERROR(N10*(1+Outros!$B$4/100),"") -> 9.8356646 | P10: =IFERROR(O10*Q$5,"") -> 14.753497 | Q10: =IFERROR(P10/(1-Outros!$B$6-Outros!$B$7)+Outros!$B$8,"") -> 22.441871 | R10: 45 | T10: 45 | U10: =IF(OR(T10="",T10=0),"",(T10-O10)/O10) -> 3.5751865
A11: 46065 | B11: Fabiano Boneco | C11: A1 Combo | D11: National3D PLA High Speed | E11: 80.68 | F11: 0.19444444 | G11: 0 | H11: 0 | I11: 0 | J11: =IFERROR(E11/1000*VLOOKUP(D11,Filamentos!A$2:I$96,9,FALSE),"") -> 8.068 | K11: =IFERROR(F11*24*VLOOKUP(C11,Impressoras!A$2:G$100,6,FALSE)*Outros!$B$2,"") -> 0.602 | L11: =IFERROR(F11*24*VLOOKUP(C11,Impressoras!A$2:G$100,7,FALSE),"") -> 2.6953687 | M11: =IFERROR(G11*24*Outros!$B$3,"") -> 0 | N11: =IFERROR(SUM(J11:M11),"") -> 11.365369 | O11: =IFERROR(N11*(1+Outros!$B$4/100),"") -> 12.501906 | P11: =IFERROR(O11*Q$5,"") -> 18.752858 | Q11: =IFERROR(P11/(1-Outros!$B$6-Outros!$B$7)+Outros!$B$8,"") -> 27.441073 | R11: 150 | T11: 150 | U11: =IF(OR(T11="",T11=0),"",(T11-O11)/O11) -> 10.998171
A12: 46065 | B12: Cristiane Mengue | C12: A1 Combo | D12: National3D PLA High Speed | E12: 84.28 | F12: 0.19305556 | G12: 0.020833333 | H12: 0 | I12: 0 | J12: =IFERROR(E12/1000*VLOOKUP(D12,Filamentos!A$2:I$96,9,FALSE),"") -> 8.428 | K12: =IFERROR(F12*24*VLOOKUP(C12,Impressoras!A$2:G$100,6,FALSE)*Outros!$B$2,"") -> 0.5977 | L12: =IFERROR(F12*24*VLOOKUP(C12,Impressoras!A$2:G$100,7,FALSE),"") -> 2.676116 | M12: =IFERROR(G12*24*Outros!$B$3,"") -> 5 | N12: =IFERROR(SUM(J12:M12),"") -> 16.701816 | O12: =IFERROR(N12*(1+Outros!$B$4/100),"") -> 18.371998 | P12: =IFERROR(O12*Q$5,"") -> 27.557996 | Q12: =IFERROR(P12/(1-Outros!$B$6-Outros!$B$7)+Outros!$B$8,"") -> 38.447496 | R12: 50 | T12: 50 | U12: =IF(OR(T12="",T12=0),"",(T12-O12)/O12) -> 1.7215331
A13: 46062 | B13: Tom Formatura | C13: A1 Combo | D13: National3D PLA High Speed | E13: 864.07 | F13: 2.8263889 | G13: 0.020833333 | H13: 0 | I13: 0 | J13: =IFERROR(E13/1000*VLOOKUP(D13,Filamentos!A$2:I$96,9,FALSE),"") -> 86.407 | K13: =IFERROR(F13*24*VLOOKUP(C13,Impressoras!A$2:G$100,6,FALSE)*Outros!$B$2,"") -> 8.7505 | L13: =IFERROR(F13*24*VLOOKUP(C13,Impressoras!A$2:G$100,7,FALSE),"") -> 39.179109 | M13: =IFERROR(G13*24*Outros!$B$3,"") -> 5 | N13: =IFERROR(SUM(J13:M13),"") -> 139.33661 | O13: =IFERROR(N13*(1+Outros!$B$4/100),"") -> 153.27027 | P13: =IFERROR(O13*Q$5,"") -> 229.9054 | Q13: =IFERROR(P13/(1-Outros!$B$6-Outros!$B$7)+Outros!$B$8,"") -> 291.38176 | R13: 0 | S13: 0 | T13: 0 | U13: =IF(OR(T13="",T13=0),"",(T13-O13)/O13)
A14: 46065 | B14: Incenso Pescador | C14: A1 Combo | D14: National3D PLA High Speed | E14: 26.3 | F14: 0.10972222 | G14: 0 | H14: 0 | I14: 0 | J14: =IFERROR(E14/1000*VLOOKUP(D14,Filamentos!A$2:I$96,9,FALSE),"") -> 2.63 | K14: =IFERROR(F14*24*VLOOKUP(C14,Impressoras!A$2:G$100,6,FALSE)*Outros!$B$2,"") -> 0.3397 | L14: =IFERROR(F14*24*VLOOKUP(C14,Impressoras!A$2:G$100,7,FALSE),"") -> 1.520958 | M14: =IFERROR(G14*24*Outros!$B$3,"") -> 0 | N14: =IFERROR(SUM(J14:M14),"") -> 4.490658 | O14: =IFERROR(N14*(1+Outros!$B$4/100),"") -> 4.9397238 | P14: =IFERROR(O14*Q$5,"") -> 7.4095858 | Q14: =IFERROR(P14/(1-Outros!$B$6-Outros!$B$7)+Outros!$B$8,"") -> 13.261982 | R14: 20 | S14: 15 | U14: =IF(OR(T14="",T14=0),"",(T14-O14)/O14)
A15: 46063 | B15: V. Feliz Suculentas | C15: A1 Combo | D15: National3D PLA High Speed | E15: 64.01 | F15: 0.089583333 | G15: 0 | H15: 0 | I15: 0 | J15: =IFERROR(E15/1000*VLOOKUP(D15,Filamentos!A$2:I$96,9,FALSE),"") -> 6.401 | K15: =IFERROR(F15*24*VLOOKUP(C15,Impressoras!A$2:G$100,6,FALSE)*Outros!$B$2,"") -> 0.27735 | L15: =IFERROR(F15*24*VLOOKUP(C15,Impressoras!A$2:G$100,7,FALSE),"") -> 1.2417948 | M15: =IFERROR(G15*24*Outros!$B$3,"") -> 0 | N15: =IFERROR(SUM(J15:M15),"") -> 7.9201449 | O15: =IFERROR(N15*(1+Outros!$B$4/100),"") -> 8.7121593 | P15: =IFERROR(O15*Q$5,"") -> 13.068239 | Q15: =IFERROR(P15/(1-Outros!$B$6-Outros!$B$7)+Outros!$B$8,"") -> 20.335299 | R15: 20 | S15: 15 | U15: =IF(OR(T15="",T15=0),"",(T15-O15)/O15)
A16: 46067 | B16: Raquete Chaveiro | C16: A1 Combo | D16: National3D PLA High Speed | E16: 24.29 | F16: 0.090277778 | G16: 0 | H16: 0 | I16: 0 | J16: =IFERROR(E16/1000*VLOOKUP(D16,Filamentos!A$2:I$96,9,FALSE),"") -> 2.429 | K16: =IFERROR(F16*24*VLOOKUP(C16,Impressoras!A$2:G$100,6,FALSE)*Outros!$B$2,"") -> 0.2795 | L16: =IFERROR(F16*24*VLOOKUP(C16,Impressoras!A$2:G$100,7,FALSE),"") -> 1.2514212 | M16: =IFERROR(G16*24*Outros!$B$3,"") -> 0 | N16: =IFERROR(SUM(J16:M16),"") -> 3.9599212 | O16: =IFERROR(N16*(1+Outros!$B$4/100),"") -> 4.3559133 | P16: =IFERROR(O16*Q$5,"") -> 6.5338699 | Q16: =IFERROR(P16/(1-Outros!$B$6-Outros!$B$7)+Outros!$B$8,"") -> 12.167337 | R16: 10 | S16: 7 | U16: =IF(OR(T16="",T16=0),"",(T16-O16)/O16)
A17: 46063 | B17: V Felicia Espiral | C17: A1 Combo | D17: National3D PLA High Speed | E17: 279.52 | F17: 0.17916667 | G17: 0 | H17: 0 | I17: 0 | J17: =IFERROR(E17/1000*VLOOKUP(D17,Filamentos!A$2:I$96,9,FALSE),"") -> 27.952 | K17: =IFERROR(F17*24*VLOOKUP(C17,Impressoras!A$2:G$100,6,FALSE)*Outros!$B$2,"") -> 0.5547 | L17: =IFERROR(F17*24*VLOOKUP(C17,Impressoras!A$2:G$100,7,FALSE),"") -> 2.4835897 | M17: =IFERROR(G17*24*Outros!$B$3,"") -> 0 | N17: =IFERROR(SUM(J17:M17),"") -> 30.99029 | O17: =IFERROR(N17*(1+Outros!$B$4/100),"") -> 34.089319 | P17: =IFERROR(O17*Q$5,"") -> 51.133978 | Q17: =IFERROR(P17/(1-Outros!$B$6-Outros!$B$7)+Outros!$B$8,"") -> 67.917473 | R17: 70 | S17: 60 | U17: =IF(OR(T17="",T17=0),"",(T17-O17)/O17)
A18: 46063 | B18: Coelho 5x 5cm | C18: A1 Combo | D18: National3D PLA High Speed | E18: 35.8 | F18: 0.063194444 | G18: 0 | H18: 0 | I18: 0 | J18: =IFERROR(E18/1000*VLOOKUP(D18,Filamentos!A$2:I$96,9,FALSE),"") -> 3.58 | K18: =IFERROR(F18*24*VLOOKUP(C18,Impressoras!A$2:G$100,6,FALSE)*Outros!$B$2,"") -> 0.19565 | L18: =IFERROR(F18*24*VLOOKUP(C18,Impressoras!A$2:G$100,7,FALSE),"") -> 0.87599482 | M18: =IFERROR(G18*24*Outros!$B$3,"") -> 0 | N18: =IFERROR(SUM(J18:M18),"") -> 4.6516448 | O18: =IFERROR(N18*(1+Outros!$B$4/100),"") -> 5.1168093 | P18: =IFERROR(O18*Q$5,"") -> 7.6752139 | Q18: =IFERROR(P18/(1-Outros!$B$6-Outros!$B$7)+Outros!$B$8,"") -> 13.594017 | R18: 10 | S18: 7.5 | U18: =IF(OR(T18="",T18=0),"",(T18-O18)/O18)
A19: 46069 | B19: Raquel Shitzu | C19: A1 Combo | D19: Masterprint PETG Basic | E19: 47 | F19: 0.10902778 | G19: 0.0625 | H19: 0 | I19: 0 | J19: =IFERROR(E19/1000*VLOOKUP(D19,Filamentos!A$2:I$96,9,FALSE),"") -> 2.9093 | K19: =IFERROR(F19*24*VLOOKUP(C19,Impressoras!A$2:G$100,6,FALSE)*Outros!$B$2,"") -> 0.33755 | L19: =IFERROR(F19*24*VLOOKUP(C19,Impressoras!A$2:G$100,7,FALSE),"") -> 1.5113317 | M19: =IFERROR(G19*24*Outros!$B$3,"") -> 15 | N19: =IFERROR(SUM(J19:M19),"") -> 19.758182 | O19: =IFERROR(N19*(1+Outros!$B$4/100),"") -> 21.734 | P19: =IFERROR(O19*Q$5,"") -> 32.601 | Q19: =IFERROR(P19/(1-Outros!$B$6-Outros!$B$7)+Outros!$B$8,"") -> 44.75125 | R19: 0 | S19: 0 | T19: 0 | U19: =IF(OR(T19="",T19=0),"",(T19-O19)/O19)
A20: 46069 | B20: Vaso Voronoi 20cm | C20: A1 Combo | D20: Masterprint PETG Basic | E20: 174.86 | F20: 0.41666667 | G20: 0 | H20: 0 | I20: 0 | J20: =IFERROR(E20/1000*VLOOKUP(D20,Filamentos!A$2:I$96,9,FALSE),"") -> 10.823834 | K20: =IFERROR(F20*24*VLOOKUP(C20,Impressoras!A$2:G$100,6,FALSE)*Outros!$B$2,"") -> 1.29 | L20: =IFERROR(F20*24*VLOOKUP(C20,Impressoras!A$2:G$100,7,FALSE),"") -> 5.77579 | M20: =IFERROR(G20*24*Outros!$B$3,"") -> 0 | N20: =IFERROR(SUM(J20:M20),"") -> 17.889624 | O20: =IFERROR(N20*(1+Outros!$B$4/100),"") -> 19.678586 | P20: =IFERROR(O20*Q$5,"") -> 29.51788 | Q20: =IFERROR(P20/(1-Outros!$B$6-Outros!$B$7)+Outros!$B$8,"") -> 40.89735 | R20: 50 | S20: 40 | U20: =IF(OR(T20="",T20=0),"",(T20-O20)/O20)
A21: 46071 | B21: Fabiano Vaso c Pés | C21: A1 Combo | D21: National3D PLA High Speed | E21: 73.9 | F21: 0.24930556 | G21: 0 | H21: 0 | I21: 0 | J21: =IFERROR(E21/1000*VLOOKUP(D21,Filamentos!A$2:I$96,9,FALSE),"") -> 7.39 | K21: =IFERROR(F21*24*VLOOKUP(C21,Impressoras!A$2:G$100,6,FALSE)*Outros!$B$2,"") -> 0.77185 | L21: =IFERROR(F21*24*VLOOKUP(C21,Impressoras!A$2:G$100,7,FALSE),"") -> 3.4558477 | M21: =IFERROR(G21*24*Outros!$B$3,"") -> 0 | N21: =IFERROR(SUM(J21:M21),"") -> 11.617698 | O21: =IFERROR(N21*(1+Outros!$B$4/100),"") -> 12.779467 | P21: =IFERROR(O21*Q$5,"") -> 19.169201 | Q21: =IFERROR(P21/(1-Outros!$B$6-Outros!$B$7)+Outros!$B$8,"") -> 27.961501 | R21: 30 | S21: 20 | T21: 50 | U21: =IF(OR(T21="",T21=0),"",(T21-O21)/O21) -> 2.9125261
A22: 46072 | B22: Claro S. Base | C22: A1 Combo | D22: National3D PLA High Speed | E22: 99.92 | F22: 0.14583333 | G22: 0.020833333 | H22: 0 | I22: 0 | J22: =IFERROR(E22/1000*VLOOKUP(D22,Filamentos!A$2:I$96,9,FALSE),"") -> 9.992 | K22: =IFERROR(F22*24*VLOOKUP(C22,Impressoras!A$2:G$100,6,FALSE)*Outros!$B$2,"") -> 0.4515 | L22: =IFERROR(F22*24*VLOOKUP(C22,Impressoras!A$2:G$100,7,FALSE),"") -> 2.0215265 | M22: =IFERROR(G22*24*Outros!$B$3,"") -> 5 | N22: =IFERROR(SUM(J22:M22),"") -> 17.465027 | O22: =IFERROR(N22*(1+Outros!$B$4/100),"") -> 19.211529 | P22: =IFERROR(O22*Q$5,"") -> 28.817294 | Q22: =IFERROR(P22/(1-Outros!$B$6-Outros!$B$7)+Outros!$B$8,"") -> 40.021617 | R22: 65 | T22: 65 | U22: =IF(OR(T22="",T22=0),"",(T22-O22)/O22) -> 2.383385
A23: 46072 | B23: Claro S. Boneco | C23: A1 Combo | D23: National3D PLA High Speed | E23: 98.04 | F23: 0.27708333 | G23: 0.0625 | H23: 0 | I23: 0 | J23: =IFERROR(E23/1000*VLOOKUP(D23,Filamentos!A$2:I$96,9,FALSE),"") -> 9.804 | K23: =IFERROR(F23*24*VLOOKUP(C23,Impressoras!A$2:G$100,6,FALSE)*Outros!$B$2,"") -> 0.85785 | L23: =IFERROR(F23*24*VLOOKUP(C23,Impressoras!A$2:G$100,7,FALSE),"") -> 3.8409004 | M23: =IFERROR(G23*24*Outros!$B$3,"") -> 15 | N23: =IFERROR(SUM(J23:M23),"") -> 29.50275 | O23: =IFERROR(N23*(1+Outros!$B$4/100),"") -> 32.453025 | P23: =IFERROR(O23*Q$5,"") -> 48.679538 | Q23: =IFERROR(P23/(1-Outros!$B$6-Outros!$B$7)+Outros!$B$8,"") -> 64.849423 | R23: 170 | T23: 170 | U23: =IF(OR(T23="",T23=0),"",(T23-O23)/O23) -> 4.2383406
A24: 46073 | B24: Daniel Spectreman | C24: A1 Combo | D24: Masterprint PETG Basic | E24: 58.42 | F24: 0.13958333 | G24: 0.083333333 | H24: 0 | I24: 0 | J24: =IFERROR(E24/1000*VLOOKUP(D24,Filamentos!A$2:I$96,9,FALSE),"") -> 3.616198 | K24: =IFERROR(F24*24*VLOOKUP(C24,Impressoras!A$2:G$100,6,FALSE)*Outros!$B$2,"") -> 0.43215 | L24: =IFERROR(F24*24*VLOOKUP(C24,Impressoras!A$2:G$100,7,FALSE),"") -> 1.9348896 | M24: =IFERROR(G24*24*Outros!$B$3,"") -> 20 | N24: =IFERROR(SUM(J24:M24),"") -> 25.983238 | O24: =IFERROR(N24*(1+Outros!$B$4/100),"") -> 28.581561 | P24: =IFERROR(O24*Q$5,"") -> 42.872342 | Q24: =IFERROR(P24/(1-Outros!$B$6-Outros!$B$7)+Outros!$B$8,"") -> 57.590428 | U24: =IF(OR(T24="",T24=0),"",(T24-O24)/O24)
A25: 46074 | B25: Felipe Esculura | C25: A1 Combo | D25: Masterprint PETG Basic | E25: 100.99 | F25: 0.34097222 | G25: 0.020833333 | H25: 0 | I25: 0 | J25: =IFERROR(E25/1000*VLOOKUP(D25,Filamentos!A$2:I$96,9,FALSE),"") -> 6.251281 | K25: =IFERROR(F25*24*VLOOKUP(C25,Impressoras!A$2:G$100,6,FALSE)*Outros!$B$2,"") -> 1.05565 | L25: =IFERROR(F25*24*VLOOKUP(C25,Impressoras!A$2:G$100,7,FALSE),"") -> 4.7265215 | M25: =IFERROR(G25*24*Outros!$B$3,"") -> 5 | N25: =IFERROR(SUM(J25:M25),"") -> 17.033452 | O25: =IFERROR(N25*(1+Outros!$B$4/100),"") -> 18.736798 | P25: =IFERROR(O25*Q$5,"") -> 28.105197 | Q25: =IFERROR(P25/(1-Outros!$B$6-Outros!$B$7)+Outros!$B$8,"") -> 39.131496 | R25: 60 | S25: 35 | T25: 50 | U25: =IF(OR(T25="",T25=0),"",(T25-O25)/O25) -> 1.6685456
A26: 46074 | B26: Felipe Portal Vela | C26: A1 Combo | D26: Masterprint PETG Basic | E26: 291.17 | F26: 1.4159722 | G26: 0.020833333 | H26: 0 | I26: 0 | J26: =IFERROR(E26/1000*VLOOKUP(D26,Filamentos!A$2:I$96,9,FALSE),"") -> 18.023423 | K26: =IFERROR(F26*24*VLOOKUP(C26,Impressoras!A$2:G$100,6,FALSE)*Outros!$B$2,"") -> 4.38385 | L26: =IFERROR(F26*24*VLOOKUP(C26,Impressoras!A$2:G$100,7,FALSE),"") -> 19.62806 | M26: =IFERROR(G26*24*Outros!$B$3,"") -> 5 | N26: =IFERROR(SUM(J26:M26),"") -> 47.035333 | O26: =IFERROR(N26*(1+Outros!$B$4/100),"") -> 51.738866 | P26: =IFERROR(O26*Q$5,"") -> 77.608299 | Q26: =IFERROR(P26/(1-Outros!$B$6-Outros!$B$7)+Outros!$B$8,"") -> 101.01037 | R26: 150 | S26: 70 | T26: 130 | U26: =IF(OR(T26="",T26=0),"",(T26-O26)/O26) -> 1.5126179
A27: 46075 | B27: Felipe Recip. P. Vela | C27: A1 Combo | D27: Masterprint PETG Basic | E27: 44.48 | F27: 0.12222222 | G27: 0 | H27: 0 | I27: 0 | J27: =IFERROR(E27/1000*VLOOKUP(D27,Filamentos!A$2:I$96,9,FALSE),"") -> 2.753312 | K27: =IFERROR(F27*24*VLOOKUP(C27,Impressoras!A$2:G$100,6,FALSE)*Outros!$B$2,"") -> 0.3784 | L27: =IFERROR(F27*24*VLOOKUP(C27,Impressoras!A$2:G$100,7,FALSE),"") -> 1.6942317 | M27: =IFERROR(G27*24*Outros!$B$3,"") -> 0 | N27: =IFERROR(SUM(J27:M27),"") -> 4.8259437 | O27: =IFERROR(N27*(1+Outros!$B$4/100),"") -> 5.3085381 | P27: =IFERROR(O27*Q$5,"") -> 7.9628072 | Q27: =IFERROR(P27/(1-Outros!$B$6-Outros!$B$7)+Outros!$B$8,"") -> 13.953509 | T27: 20 | U27: =IF(OR(T27="",T27=0),"",(T27-O27)/O27) -> 2.7675156
A28: 46083 | B28: Bach Ch. Glock | C28: A1 Combo | D28: National3D PLA High Speed | E28: =(E30/10)*16 -> 90.992 | F28: =(F30/10)*16 -> 0.35888889 | G28: 0.020833333 | H28: 26.5 | I28: 0 | J28: =IFERROR(E28/1000*VLOOKUP(D28,Filamentos!A$2:I$96,9,FALSE),"") -> 9.0992 | K28: =IFERROR(F28*24*VLOOKUP(C28,Impressoras!A$2:G$100,6,FALSE)*Outros!$B$2,"") -> 1.11112 | L28: =IFERROR(F28*24*VLOOKUP(C28,Impressoras!A$2:G$100,7,FALSE),"") -> 4.9748805 | M28: =IFERROR(G28*24*Outros!$B$3,"") -> 5 | N28: =IFERROR(SUM(J28:M28),"") -> 20.1852 | O28: =IFERROR(N28*(1+Outros!$B$4/100),"") -> 22.20372 | P28: =IFERROR(O28*Q$5,"") -> 33.305581 | Q28: =IFERROR(P28/(1-Outros!$B$6-Outros!$B$7)+Outros!$B$8,"") -> 45.631976 | R28: 90 | S28: 50 | T28: 104 | U28: =IF(OR(T28="",T28=0),"",(T28-O28)/O28) -> 3.6838997
A29: 46076 | B29: V Felicia Espiral | C29: A1 Combo | D29: National3D PLA High Speed | E29: 179.6 | F29: 0.11319444 | G29: 0.020833333 | H29: 0 | I29: 0 | J29: =IFERROR(E29/1000*VLOOKUP(D29,Filamentos!A$2:I$96,9,FALSE),"") -> 17.96 | K29: =IFERROR(F29*24*VLOOKUP(C29,Impressoras!A$2:G$100,6,FALSE)*Outros!$B$2,"") -> 0.35045 | L29: =IFERROR(F29*24*VLOOKUP(C29,Impressoras!A$2:G$100,7,FALSE),"") -> 1.5690896 | M29: =IFERROR(G29*24*Outros!$B$3,"") -> 5 | N29: =IFERROR(SUM(J29:M29),"") -> 24.87954 | O29: =IFERROR(N29*(1+Outros!$B$4/100),"") -> 27.367494 | P29: =IFERROR(O29*Q$5,"") -> 41.05124 | Q29: =IFERROR(P29/(1-Outros!$B$6-Outros!$B$7)+Outros!$B$8,"") -> 55.31405 | R29: 65 | S29: 60 | T29: 65 | U29: =IF(OR(T29="",T29=0),"",(T29-O29)/O29) -> 1.3750805
A30: 46077 | B30: Olguins Ch. Glock | C30: A1 Combo | D30: Masterprint PETG Basic | E30: =47.35+9.52 -> 56.87 | F30: 0.22430556 | G30: 0.020833333 | H30: 2.7 | I30: 0.1 | J30: =IFERROR(E30/1000*VLOOKUP(D30,Filamentos!A$2:I$96,9,FALSE),"") -> 3.520253 | K30: =IFERROR(F30*24*VLOOKUP(C30,Impressoras!A$2:G$100,6,FALSE)*Outros!$B$2,"") -> 0.69445 | L30: =IFERROR(F30*24*VLOOKUP(C30,Impressoras!A$2:G$100,7,FALSE),"") -> 3.1093003 | M30: =IFERROR(G30*24*Outros!$B$3,"") -> 5 | N30: =IFERROR(SUM(J30:M30),"") -> 12.324003 | O30: =IFERROR(N30*(1+Outros!$B$4/100),"") -> 13.556404 | P30: =IFERROR(O30*Q$5,"") -> 20.334605 | Q30: =IFERROR(P30/(1-Outros!$B$6-Outros!$B$7)+Outros!$B$8,"") -> 29.418257 | R30: 65 | S30: 35 | T30: 65 | U30: =IF(OR(T30="",T30=0),"",(T30-O30)/O30) -> 3.794782
A31: 46083 | B31: Bach. Munição | C31: A1 Combo | D31: Masterprint PETG Basic | E31: =16.1+145.5+2.5 -> 164.1 | F31: 0.33194444 | G31: 0 | H31: 0 | I31: 0 | J31: =IFERROR(E31/1000*VLOOKUP(D31,Filamentos!A$2:I$96,9,FALSE),"") -> 10.15779 | K31: =IFERROR(F31*24*VLOOKUP(C31,Impressoras!A$2:G$100,6,FALSE)*Outros!$B$2,"") -> 1.0277 | L31: =IFERROR(F31*24*VLOOKUP(C31,Impressoras!A$2:G$100,7,FALSE),"") -> 4.6013794 | M31: =IFERROR(G31*24*Outros!$B$3,"") -> 0 | N31: =IFERROR(SUM(J31:M31),"") -> 15.786869 | O31: =IFERROR(N31*(1+Outros!$B$4/100),"") -> 17.365556 | P31: =IFERROR(O31*Q$5,"") -> 26.048334 | Q31: =IFERROR(P31/(1-Outros!$B$6-Outros!$B$7)+Outros!$B$8,"") -> 36.560418 | R31: 80 | S31: 50 | T31: 100 | U31: =IF(OR(T31="",T31=0),"",(T31-O31)/O31) -> 4.7585256
A32: 46083 | B32: Daniel Soldadinhos | C32: A1 Combo | D32: National3D PLA High Speed | E32: 120.22 | F32: 0.38263889 | G32: 0 | H32: 0 | I32: 0 | J32: =IFERROR(E32/1000*VLOOKUP(D32,Filamentos!A$2:I$96,9,FALSE),"") -> 12.022 | K32: =IFERROR(F32*24*VLOOKUP(C32,Impressoras!A$2:G$100,6,FALSE)*Outros!$B$2,"") -> 1.18465 | L32: =IFERROR(F32*24*VLOOKUP(C32,Impressoras!A$2:G$100,7,FALSE),"") -> 5.3041005 | M32: =IFERROR(G32*24*Outros!$B$3,"") -> 0 | N32: =IFERROR(SUM(J32:M32),"") -> 18.51075 | O32: =IFERROR(N32*(1+Outros!$B$4/100),"") -> 20.361826 | P32: =IFERROR(O32*Q$5,"") -> 30.542738 | Q32: =IFERROR(P32/(1-Outros!$B$6-Outros!$B$7)+Outros!$B$8,"") -> 42.178423 | R32: 0 | S32: 0 | T32: 0 | U32: =IF(OR(T32="",T32=0),"",(T32-O32)/O32)
B33: Thais Velasques 01 | C33: A1 Combo | D33: National3D PLA High Speed | E33: 5 | F33: 0.0069444444 | G33: 0 | H33: 0.27 | I33: 0 | J33: =IFERROR(E33/1000*VLOOKUP(D33,Filamentos!A$2:I$96,9,FALSE),"") -> 0.5 | K33: =IFERROR(F33*24*VLOOKUP(C33,Impressoras!A$2:G$100,6,FALSE)*Outros!$B$2,"") -> 0.0215 | L33: =IFERROR(F33*24*VLOOKUP(C33,Impressoras!A$2:G$100,7,FALSE),"") -> 0.096263167 | M33: =IFERROR(G33*24*Outros!$B$3,"") -> 0 | N33: =IFERROR(SUM(J33:M33),"") -> 0.61776317 | O33: =IFERROR(N33*(1+Outros!$B$4/100),"") -> 0.67953948 | P33: =IFERROR(O33*Q$5,"") -> 1.0193092 | Q33: =IFERROR(P33/(1-Outros!$B$6-Outros!$B$7)+Outros!$B$8,"") -> 5.2741365 | R33: 5 | S33: 3 | T33: 0 | U33: =IF(OR(T33="",T33=0),"",(T33-O33)/O33)
B34: Thais Velasques 50 | C34: A1 Combo | D34: National3D PLA High Speed | E34: 22.41 | F34: 0.066666667 | G34: 0 | H34: =0.27*50 -> 13.5 | I34: 1 | J34: =IFERROR(E34/1000*VLOOKUP(D34,Filamentos!A$2:I$96,9,FALSE),"") -> 2.241 | K34: =IFERROR(F34*24*VLOOKUP(C34,Impressoras!A$2:G$100,6,FALSE)*Outros!$B$2,"") -> 0.2064 | L34: =IFERROR(F34*24*VLOOKUP(C34,Impressoras!A$2:G$100,7,FALSE),"") -> 0.9241264 | M34: =IFERROR(G34*24*Outros!$B$3,"") -> 0 | N34: =IFERROR(SUM(J34:M34),"") -> 3.3715264 | O34: =IFERROR(N34*(1+Outros!$B$4/100),"") -> 3.708679 | P34: =IFERROR(O34*Q$5,"") -> 5.5630186 | Q34: =IFERROR(P34/(1-Outros!$B$6-Outros!$B$7)+Outros!$B$8,"") -> 10.953773 | R34: 7 | S34: 5 | T34: 0 | U34: =IF(OR(T34="",T34=0),"",(T34-O34)/O34)
B35: Thais Velasques 100 | C35: A1 Combo | D35: National3D PLA High Speed | E35: 44.3 | F35: 0.12708333 | G35: 0 | H35: =0.27*100 -> 27 | I35: 1.5 | J35: =IFERROR(E35/1000*VLOOKUP(D35,Filamentos!A$2:I$96,9,FALSE),"") -> 4.43 | K35: =IFERROR(F35*24*VLOOKUP(C35,Impressoras!A$2:G$100,6,FALSE)*Outros!$B$2,"") -> 0.39345 | L35: =IFERROR(F35*24*VLOOKUP(C35,Impressoras!A$2:G$100,7,FALSE),"") -> 1.7616159 | M35: =IFERROR(G35*24*Outros!$B$3,"") -> 0 | N35: =IFERROR(SUM(J35:M35),"") -> 6.5850659 | O35: =IFERROR(N35*(1+Outros!$B$4/100),"") -> 7.2435725 | P35: =IFERROR(O35*Q$5,"") -> 10.865359 | Q35: =IFERROR(P35/(1-Outros!$B$6-Outros!$B$7)+Outros!$B$8,"") -> 17.581699 | R35: 7 | S35: 5 | T35: 0 | U35: =IF(OR(T35="",T35=0),"",(T35-O35)/O35)
B36: Thais Velasques 130 | C36: A1 Combo | D36: National3D PLA High Speed | E36: 57.89 | F36: 0.16458333 | G36: 0 | H36: =0.27*131 -> 35.37 | I36: 1.5 | J36: =IFERROR(E36/1000*VLOOKUP(D36,Filamentos!A$2:I$96,9,FALSE),"") -> 5.789 | K36: =IFERROR(F36*24*VLOOKUP(C36,Impressoras!A$2:G$100,6,FALSE)*Outros!$B$2,"") -> 0.50955 | L36: =IFERROR(F36*24*VLOOKUP(C36,Impressoras!A$2:G$100,7,FALSE),"") -> 2.2814371 | M36: =IFERROR(G36*24*Outros!$B$3,"") -> 0 | N36: =IFERROR(SUM(J36:M36),"") -> 8.579987 | O36: =IFERROR(N36*(1+Outros!$B$4/100),"") -> 9.4379858 | P36: =IFERROR(O36*Q$5,"") -> 14.156979 | Q36: =IFERROR(P36/(1-Outros!$B$6-Outros!$B$7)+Outros!$B$8,"") -> 21.696223 | R36: 2.5 | S36: 2 | T36: 230 | U36: =IF(OR(T36="",T36=0),"",(T36-O36)/O36) -> 23.369607
B37: Thais 2 Cores 01 | C37: A1 Combo | D37: Bambu Lite | E37: 7.28 | F37: 0.024305556 | G37: 0 | H37: 0.27 | I37: 0 | J37: =IFERROR(E37/1000*VLOOKUP(D37,Filamentos!A$2:I$96,9,FALSE),"") -> 0.546 | K37: =IFERROR(F37*24*VLOOKUP(C37,Impressoras!A$2:G$100,6,FALSE)*Outros!$B$2,"") -> 0.07525 | L37: =IFERROR(F37*24*VLOOKUP(C37,Impressoras!A$2:G$100,7,FALSE),"") -> 0.33692108 | M37: =IFERROR(G37*24*Outros!$B$3,"") -> 0 | N37: =IFERROR(SUM(J37:M37),"") -> 0.95817108 | O37: =IFERROR(N37*(1+Outros!$B$4/100),"") -> 1.0539882 | P37: =IFERROR(O37*Q$5,"") -> 1.5809823 | Q37: =IFERROR(P37/(1-Outros!$B$6-Outros!$B$7)+Outros!$B$8,"") -> 5.9762279 | R37: 5 | S37: 3 | T37: 0 | U37: =IF(OR(T37="",T37=0),"",(T37-O37)/O37)
B38: Thais 2 Cores 50 | C38: A1 Combo | D38: Bambu Lite | E38: 77.7 | F38: 0.16458333 | G38: 0 | H38: =0.27*50 -> 13.5 | I38: 1 | J38: =IFERROR(E38/1000*VLOOKUP(D38,Filamentos!A$2:I$96,9,FALSE),"") -> 5.8275 | K38: =IFERROR(F38*24*VLOOKUP(C38,Impressoras!A$2:G$100,6,FALSE)*Outros!$B$2,"") -> 0.50955 | L38: =IFERROR(F38*24*VLOOKUP(C38,Impressoras!A$2:G$100,7,FALSE),"") -> 2.2814371 | M38: =IFERROR(G38*24*Outros!$B$3,"") -> 0 | N38: =IFERROR(SUM(J38:M38),"") -> 8.6184871 | O38: =IFERROR(N38*(1+Outros!$B$4/100),"") -> 9.4803358 | P38: =IFERROR(O38*Q$5,"") -> 14.220504 | Q38: =IFERROR(P38/(1-Outros!$B$6-Outros!$B$7)+Outros!$B$8,"") -> 21.77563 | R38: 7 | S38: 5 | T38: 0 | U38: =IF(OR(T38="",T38=0),"",(T38-O38)/O38)
B39: Thais 2 Cores 100 | C39: A1 Combo | D39: Bambu Lite | E39: 44.3 | F39: 0.12708333 | G39: 0 | H39: =0.27*100 -> 27 | I39: 1.5 | J39: =IFERROR(E39/1000*VLOOKUP(D39,Filamentos!A$2:I$96,9,FALSE),"") -> 3.3225 | K39: =IFERROR(F39*24*VLOOKUP(C39,Impressoras!A$2:G$100,6,FALSE)*Outros!$B$2,"") -> 0.39345 | L39: =IFERROR(F39*24*VLOOKUP(C39,Impressoras!A$2:G$100,7,FALSE),"") -> 1.7616159 | M39: =IFERROR(G39*24*Outros!$B$3,"") -> 0 | N39: =IFERROR(SUM(J39:M39),"") -> 5.4775659 | O39: =IFERROR(N39*(1+Outros!$B$4/100),"") -> 6.0253225 | P39: =IFERROR(O39*Q$5,"") -> 9.0379838 | Q39: =IFERROR(P39/(1-Outros!$B$6-Outros!$B$7)+Outros!$B$8,"") -> 15.29748 | R39: 7 | S39: 5 | T39: 0 | U39: =IF(OR(T39="",T39=0),"",(T39-O39)/O39)
B40: Thais 2 Cores 130 | C40: A1 Combo | D40: Bambu Lite | E40: 57.89 | F40: 0.16458333 | G40: 0 | H40: =0.27*131 -> 35.37 | I40: 1.5 | J40: =IFERROR(E40/1000*VLOOKUP(D40,Filamentos!A$2:I$96,9,FALSE),"") -> 4.34175 | K40: =IFERROR(F40*24*VLOOKUP(C40,Impressoras!A$2:G$100,6,FALSE)*Outros!$B$2,"") -> 0.50955 | L40: =IFERROR(F40*24*VLOOKUP(C40,Impressoras!A$2:G$100,7,FALSE),"") -> 2.2814371 | M40: =IFERROR(G40*24*Outros!$B$3,"") -> 0 | N40: =IFERROR(SUM(J40:M40),"") -> 7.1327371 | O40: =IFERROR(N40*(1+Outros!$B$4/100),"") -> 7.8460108 | P40: =IFERROR(O40*Q$5,"") -> 11.769016 | Q40: =IFERROR(P40/(1-Outros!$B$6-Outros!$B$7)+Outros!$B$8,"") -> 18.71127 | R40: 2.5 | S40: 2 | T40: 230 | U40: =IF(OR(T40="",T40=0),"",(T40-O40)/O40) -> 28.31426
B41: Olguins Escultura | C41: A1 Combo | D41: National3D PLA High Speed | E41: 177.83 | F41: 0.41597222 | G41: 0 | H41: 0 | I41: 0 | J41: =IFERROR(E41/1000*VLOOKUP(D41,Filamentos!A$2:I$96,9,FALSE),"") -> 17.783 | K41: =IFERROR(F41*24*VLOOKUP(C41,Impressoras!A$2:G$100,6,FALSE)*Outros!$B$2,"") -> 1.28785 | L41: =IFERROR(F41*24*VLOOKUP(C41,Impressoras!A$2:G$100,7,FALSE),"") -> 5.7661637 | M41: =IFERROR(G41*24*Outros!$B$3,"") -> 0 | N41: =IFERROR(SUM(J41:M41),"") -> 24.837014 | O41: =IFERROR(N41*(1+Outros!$B$4/100),"") -> 27.320715 | P41: =IFERROR(O41*Q$5,"") -> 40.981073 | Q41: =IFERROR(P41/(1-Outros!$B$6-Outros!$B$7)+Outros!$B$8,"") -> 55.226341 | R41: 60 | S41: 70 | T41: 65 | U41: =IF(OR(T41="",T41=0),"",(T41-O41)/O41) -> 1.3791471

Sheet Embalagem
A1: Tipo | B1: Valor | C1: Quantidade | D1: Unitário
A2: Almofada Colmeia | B2: 511 | C2: 600 | D2: =B2/C2 -> 0.85166667 | F2: Grande | G2: 8.6
A3: Caixa Grande | B3: 949.68 | C3: 300 | D3: =B3/C3 -> 3.1656 | F3: Pequena | G3: 4.93
A4: Caixa Pequena | B4: 699 | C4: 500 | D4: =B4/C4 -> 1.398
A5: Fita gomada | B5: 29 | C5: 150 | D5: =B5/C5 -> 0.19333333
A6: Etiqueta | B6: 20 | C6: 150 | D6: =B6/C6 -> 0.13333333
A7: Caixa Fone | B7: 0.96 | D7: 0.96
A8: Argola Chaveiro | B8: 13.5 | C8: 50 | D8: =B8/C8 -> 0.27
A9: Kit LED Bambu Lab | B9: 132.5 | C9: 5 | D9: =B9/C9 -> 26.5
D10: =B10/C10 -> #DIV/0!
D11: =B11/C11 -> #DIV/0!
D12: =B12/C12 -> #DIV/0!
A14: Embalagem Grande
A15: Material | B15: Quantidade | C15: Valor
A16: Caixa Grande | B16: 1 | C16: =IFERROR(B16*VLOOKUP(A16,$A$2:$D$12,4,FALSE),0) -> 3.1656
A17: Almofada Colmeia | B17: 6 | C17: =IFERROR(B17*VLOOKUP(A17,$A$2:$D$12,4,FALSE),0) -> 5.11
A18: Fita gomada | B18: 1 | C18: =IFERROR(B18*VLOOKUP(A18,$A$2:$D$12,4,FALSE),0) -> 0.19333333
A19: Etiqueta | B19: 1 | C19: =IFERROR(B19*VLOOKUP(A19,$A$2:$D$12,4,FALSE),0) -> 0.13333333
A20: Argola Chaveiro | B20: 1 | C20: =IFERROR(B20*VLOOKUP(A20,$A$2:$D$12,4,FALSE),0) -> 0.27
A21: Total | C21: 8.6
A23: Embalagem Pequena
A24: Material | B24: Quantidade | C24: Valor
A25: Caixa Pequena | B25: 1 | C25: =IFERROR(B25*VLOOKUP(A25,$A$2:$D$12,4,FALSE),0) -> 1.398
A26: Almofada Colmeia | B26: 5 | C26: =IFERROR(B26*VLOOKUP(A26,$A$2:$D$12,4,FALSE),0) -> 4.2583333
A27: Fita gomada | B27: 1 | C27: =IFERROR(B27*VLOOKUP(A27,$A$2:$D$12,4,FALSE),0) -> 0.19333333
A28: Etiqueta | B28: 1 | C28: =IFERROR(B28*VLOOKUP(A28,$A$2:$D$12,4,FALSE),0) -> 0.13333333
C29: =IFERROR(B29*VLOOKUP(A29,$A$2:$D$12,4,FALSE),0) -> 0
A30: Total | C30: 5.98

Sheet Impressoras
A1: Impressora | B1: Fabricante | C1: Preço [R$] | D1: Tempo Depreciação (h) | E1: Custo Manutenção (R$) | F1: Consumo Médio de Energia (kWh/h) | G1: Depreciação [R$/h]
A2: A1 Combo | B2: Bambu Lab | C2: 4775.79 | D2: 10000 | E2: 1000 | F2: 0.15 | G2: =(C2+E2)/D2 -> 0.577579
A3: H2D | B3: Bambu Lab | C3: 22000 | D3: 25000 | E3: 3000 | F3: 0.3 | G3: =(C3+E3)/D3 -> 1

Sheet Outros
A2: Custo de Energia | B2: 0.86 | C2: =B5&"/kWh" -> R$/kWh
A3: Custo de Trabalho | B3: 10 | C3: =B5&"/h" -> R$/h
A4: Taxa de falha | B4: 10 | C4: %
A5: Unidade monetária | B5: R$
A6: Taxa marketplace | B6: 0.2
A7: Imposto | B7: 0
A8: Taxa fixa | B8: 4

Sheet Filamentos
A1: Fabricante | B1: Diâmetro (mm) | C1: Preço do Carretel (R$) | D1: Peso do Carretel (kg) | E1: Densidade (g/cm³) | F1: Temperatura do bico (°C) | G1: Temp. da Mesa (°C) | H1: Comprimento por rolo (m) | I1: Valor (R$/kg)
A2: Voolt3D PLA | B2: 1.75 | C2: 89 | D2: 1 | E2: 1.24 | F2: 220 | G2: 60 | H2: =D2/E2*4/(PI()*(B2/100)^2)/10 -> 335.28362 | I2: =C2/D2 -> 89 | K2: Mais Barato
A3: Outro | B3: 1.75 | C3: 75 | D3: 1 | E3: 1.24 | F3: 260 | G3: 80 | H3: =D3/E3*4/(PI()*(B3/100)^2)/10 -> 335.28362 | I3: =C3/D3 -> 75 | K3: Valor Médio
A4: 3nmax | B4: 1.75 | C4: 100 | D4: 1 | E4: 1.24 | F4: 220 | G4: 115 | H4: =D4/E4*4/(PI()*(B4/100)^2)/10 -> 335.28362 | I4: =C4/D4 -> 100 | K4: Mais Caro
A5: Polyterra | B5: 1.75 | C5: 145 | D5: 1 | E5: 1.24 | F5: 220 | G5: 100 | H5: =D5/E5*4/(PI()*(B5/100)^2)/10 -> 335.28362 | I5: =C5/D5 -> 145
A6: Bambu Lite | B6: 1.75 | C6: 75 | D6: 1 | E6: 1.24 | F6: 220 | G6: 100 | H6: =D6/E6*4/(PI()*(B6/100)^2)/10 -> 335.28362 | I6: =C6/D6 -> 75
A7: eSUN Matte | B7: 1.75 | C7: 135 | D7: 1 | E7: 1.24 | F7: 220 | G7: 100 | H7: =D7/E7*4/(PI()*(B7/100)^2)/10 -> 335.28362 | I7: =C7/D7 -> 135
A8: Bambu TPU AMS | B8: 1.75 | C8: 175 | D8: 1 | E8: 1.24 | F8: 220 | G8: 100 | H8: =D8/E8*4/(PI()*(B8/100)^2)/10 -> 335.28362 | I8: =C8/D8 -> 175
A9: National3D PLA High Speed | B9: 1.75 | C9: 100 | D9: 1 | E9: 1.24 | F9: 220 | G9: 100 | H9: 335 | I9: =C9/D9 -> 100
A10: Masterprint PETG Basic | B10: 1.75 | C10: 61.9 | D10: 1 | E10: 1.27 | F10: 245 | G10: 80 | H10: 370 | I10: =C10/D10 -> 61.9

Sheet DRE
C1: DRE - Demonstrativo de Resultados do Exercício
A5: Mês / Ano | B5: Filamento (kg) | C5: Tempo Impressão | D5: Tempo Trabalho | E5: Insumos | F5: Embalagens | G5: Custo Total | H5: Energia Elétrica | I5: Vendas | J5: % Lucro ou Prejuízo | K5: A1 Combo | L5: H2D | M5: Horas A1 Combo | N5: Horas H2D | O5: % Vida Consumida A1 | P5: % Vida Restante A1 | Q5: % Vida Consumida H2D | R5: % Vida Restante H2D
A6: =IF(DATE(YEAR(MIN(Produtos!$A:$A)),MONTH(MIN(Produtos!$A:$A))+ROW()-ROW($A$6),1)>DATE(YEAR(MAX(Produtos!$A:$A)),MONTH(MAX(Produtos!$A:$A)),1),"",DATE(YEAR(MIN(Produtos!$A:$A)),MONTH(MIN(Produtos!$A:$A))+ROW()-ROW($A$6),1)) -> 46054 | B6: =SUMIFS(Produtos!$E:$E,Produtos!$A:$A,">="&A6,Produtos!$A:$A,"<"&EOMONTH(A6,0)+1)/1000 -> 3.07825 | C6: =SUMIFS(Produtos!$F:$F,Produtos!$A:$A,">="&A6,Produtos!$A:$A,"<"&EOMONTH(A6,0)+1) -> 8.0361111 | D6: =SUMIFS(Produtos!$G:$G,Produtos!$A:$A,">="&A6,Produtos!$A:$A,"<"&EOMONTH(A6,0)+1) -> 0.4375 | E6: =SUMIFS(Produtos!$H:$H,Produtos!$A:$A,">="&A6,Produtos!$A:$A,"<"&EOMONTH(A6,0)+1) -> 37.7 | F6: =SUMIFS(Produtos!$I:$I,Produtos!$A:$A,">="&A6,Produtos!$A:$A,"<"&EOMONTH(A6,0)+1) -> 0.1 | G6: =SUMIFS(Produtos!$J:$J,Produtos!$A:$A,">="&A6,Produtos!$A:$A,"<"&EOMONTH(A6,0)+1)+SUMIFS(Produtos!$K:$K,Produtos!$A:$A,">="&A6,Produtos!$A:$A,"<"&EOMONTH(A6,0)+1)+SUMIFS(Produtos!$L:$L,Produtos!$A:$A,">="&A6,Produtos!$A:$A,"<"&EOMONTH(A6,0)+1)+SUMIFS(Produtos!$M:$M,Produtos!$A:$A,">="&A6,Produtos!$A:$A,"<"&EOMONTH(A6,0)+1) -> 519.61914 | H6: =IFERROR(SUMIFS(Produtos!$K:$K,Produtos!$A:$A,">="&$A6,Produtos!$A:$A,"<"&EOMONTH($A6,0)+1),"") -> 24.8798 | I6: =SUMIFS(Produtos!$T:$T,Produtos!$A:$A,">="&A6,Produtos!$A:$A,"<"&EOMONTH(A6,0)+1) -> 1055 | J6: =IF(G6=0,"",(I6-G6)/G6) -> 1.0303332 | K6: =SUMIFS(Produtos!$L:$L,Produtos!$C:$C,K$5,Produtos!$A:$A,">="&A6,Produtos!$A:$A,"<"&EOMONTH(A6,0)+1) -> 111.39574 | L6: =SUMIFS(Produtos!$L:$L,Produtos!$C:$C,L$5,Produtos!$A:$A,">="&B6,Produtos!$A:$A,"<"&EOMONTH(B6,0)+1) -> 0 | M6: =IFERROR(SUMIFS(Produtos!$F:$F,Produtos!$C:$C,"A1 Combo",Produtos!$A:$A,">="&$A6,Produtos!$A:$A,"<"&EOMONTH($A6,0)+1)*24,0) -> 192.86667 | N6: =IFERROR(SUMIFS(Produtos!$F:$F,Produtos!$C:$C,"H2D",Produtos!$A:$A,">="&$A6,Produtos!$A:$A,"<"&EOMONTH($A6,0)+1)*24,0) -> 0 | O6: =IFERROR(M6/VLOOKUP("A1 Combo",Impressoras!$A:$D,4,FALSE),"") -> 0.019286667 | P6: =IFERROR(1-(M6/VLOOKUP("A1 Combo",Impressoras!$A:$D,4,FALSE)),"") -> 0.98071333 | Q6: =IFERROR(N6/VLOOKUP("H2D",Impressoras!$A:$D,4,FALSE),"") -> 0 | R6: =IFERROR(1-(N6/VLOOKUP("H2D",Impressoras!$A:$D,4,FALSE)),"") -> 1
A7: =IF(DATE(YEAR(MIN(Produtos!$A:$A)),MONTH(MIN(Produtos!$A:$A))+ROW()-ROW($A$6),1)>DATE(YEAR(MAX(Produtos!$A:$A)),MONTH(MAX(Produtos!$A:$A)),1),"",DATE(YEAR(MIN(Produtos!$A:$A)),MONTH(MIN(Produtos!$A:$A))+ROW()-ROW($A$6),1)) -> 46082 | B7: =SUMIFS(Produtos!$E:$E,Produtos!$A:$A,">="&A7,Produtos!$A:$A,"<"&EOMONTH(A7,0)+1)/1000 -> 0.375312 | C7: =SUMIFS(Produtos!$F:$F,Produtos!$A:$A,">="&A7,Produtos!$A:$A,"<"&EOMONTH(A7,0)+1) -> 1.0734722 | D7: =SUMIFS(Produtos!$G:$G,Produtos!$A:$A,">="&A7,Produtos!$A:$A,"<"&EOMONTH(A7,0)+1) -> 0.020833333 | E7: =SUMIFS(Produtos!$H:$H,Produtos!$A:$A,">="&A7,Produtos!$A:$A,"<"&EOMONTH(A7,0)+1) -> 26.5 | F7: =SUMIFS(Produtos!$I:$I,Produtos!$A:$A,">="&A7,Produtos!$A:$A,"<"&EOMONTH(A7,0)+1) -> 0 | G7: =SUMIFS(Produtos!$J:$J,Produtos!$A:$A,">="&A7,Produtos!$A:$A,"<"&EOMONTH(A7,0)+1)+SUMIFS(Produtos!$K:$K,Produtos!$A:$A,">="&A7,Produtos!$A:$A,"<"&EOMONTH(A7,0)+1)+SUMIFS(Produtos!$L:$L,Produtos!$A:$A,">="&A7,Produtos!$A:$A,"<"&EOMONTH(A7,0)+1)+SUMIFS(Produtos!$M:$M,Produtos!$A:$A,">="&A7,Produtos!$A:$A,"<"&EOMONTH(A7,0)+1) -> 54.48282 | H7: =IFERROR(SUMIFS(Produtos!$K:$K,Produtos!$A:$A,">="&$A7,Produtos!$A:$A,"<"&EOMONTH($A7,0)+1),"") -> 3.32347 | I7: =SUMIFS(Produtos!$T:$T,Produtos!$A:$A,">="&A7,Produtos!$A:$A,"<"&EOMONTH(A7,0)+1) -> 204 | J7: =IF(G7=0,"",(I7-G7)/G7) -> 2.7442996 | K7: =SUMIFS(Produtos!$L:$L,Produtos!$C:$C,K$5,Produtos!$A:$A,">="&A7,Produtos!$A:$A,"<"&EOMONTH(A7,0)+1) -> 14.88036 | L7: =SUMIFS(Produtos!$L:$L,Produtos!$C:$C,L$5,Produtos!$A:$A,">="&B7,Produtos!$A:$A,"<"&EOMONTH(B7,0)+1) -> 0 | M7: =IFERROR(SUMIFS(Produtos!$F:$F,Produtos!$C:$C,"A1 Combo",Produtos!$A:$A,">="&$A7,Produtos!$A:$A,"<"&EOMONTH($A7,0)+1)*24,0) -> 25.763333 | N7: =IFERROR(SUMIFS(Produtos!$F:$F,Produtos!$C:$C,"H2D",Produtos!$A:$A,">="&$A7,Produtos!$A:$A,"<"&EOMONTH($A7,0)+1)*24,0) -> 0 | O7: =IFERROR(M7/VLOOKUP("A1 Combo",Impressoras!$A:$D,4,FALSE),"") -> 0.0025763333 | P7: =IFERROR(1-(M7/VLOOKUP("A1 Combo",Impressoras!$A:$D,4,FALSE)),"") -> 0.99742367 | Q7: =IFERROR(N7/VLOOKUP("H2D",Impressoras!$A:$D,4,FALSE),"") -> 0 | R7: =IFERROR(1-(N7/VLOOKUP("H2D",Impressoras!$A:$D,4,FALSE)),"") -> 1
A8: =IF(DATE(YEAR(MIN(Produtos!$A:$A)),MONTH(MIN(Produtos!$A:$A))+ROW()-ROW($A$6),1)>DATE(YEAR(MAX(Produtos!$A:$A)),MONTH(MAX(Produtos!$A:$A)),1),"",DATE(YEAR(MIN(Produtos!$A:$A)),MONTH(MIN(Produtos!$A:$A))+ROW()-ROW($A$6),1)) | B8: =SUMIFS(Produtos!$E:$E,Produtos!$A:$A,">="&A8,Produtos!$A:$A,"<"&EOMONTH(A8,0)+1)/1000 -> 0 | C8: =SUMIFS(Produtos!$F:$F,Produtos!$A:$A,">="&A8,Produtos!$A:$A,"<"&EOMONTH(A8,0)+1) -> 0 | D8: =SUMIFS(Produtos!$G:$G,Produtos!$A:$A,">="&A8,Produtos!$A:$A,"<"&EOMONTH(A8,0)+1) -> 0 | E8: =SUMIFS(Produtos!$H:$H,Produtos!$A:$A,">="&A8,Produtos!$A:$A,"<"&EOMONTH(A8,0)+1) -> 0 | F8: =SUMIFS(Produtos!$I:$I,Produtos!$A:$A,">="&A8,Produtos!$A:$A,"<"&EOMONTH(A8,0)+1) -> 0 | G8: =SUMIFS(Produtos!$J:$J,Produtos!$A:$A,">="&A8,Produtos!$A:$A,"<"&EOMONTH(A8,0)+1)+SUMIFS(Produtos!$K:$K,Produtos!$A:$A,">="&A8,Produtos!$A:$A,"<"&EOMONTH(A8,0)+1)+SUMIFS(Produtos!$L:$L,Produtos!$A:$A,">="&A8,Produtos!$A:$A,"<"&EOMONTH(A8,0)+1)+SUMIFS(Produtos!$M:$M,Produtos!$A:$A,">="&A8,Produtos!$A:$A,"<"&EOMONTH(A8,0)+1) -> 0 | H8: =IFERROR(SUMIFS(Produtos!$K:$K,Produtos!$A:$A,">="&$A8,Produtos!$A:$A,"<"&EOMONTH($A8,0)+1),"") -> 0 | I8: =SUMIFS(Produtos!$T:$T,Produtos!$A:$A,">="&A8,Produtos!$A:$A,"<"&EOMONTH(A8,0)+1) -> 0 | J8: =IF(G8=0,"",(I8-G8)/G8) | K8: =SUMIFS(Produtos!$L:$L,Produtos!$C:$C,K$5,Produtos!$A:$A,">="&A8,Produtos!$A:$A,"<"&EOMONTH(A8,0)+1) -> 0 | L8: =SUMIFS(Produtos!$L:$L,Produtos!$C:$C,L$5,Produtos!$A:$A,">="&B8,Produtos!$A:$A,"<"&EOMONTH(B8,0)+1) -> 0 | M8: =IFERROR(SUMIFS(Produtos!$F:$F,Produtos!$C:$C,"A1 Combo",Produtos!$A:$A,">="&$A8,Produtos!$A:$A,"<"&EOMONTH($A8,0)+1)*24,0) -> 0 | N8: =IFERROR(SUMIFS(Produtos!$F:$F,Produtos!$C:$C,"H2D",Produtos!$A:$A,">="&$A8,Produtos!$A:$A,"<"&EOMONTH($A8,0)+1)*24,0) -> 0 | O8: =IFERROR(M8/VLOOKUP("A1 Combo",Impressoras!$A:$D,4,FALSE),"") -> 0 | P8: =IFERROR(1-(M8/VLOOKUP("A1 Combo",Impressoras!$A:$D,4,FALSE)),"") -> 1 | Q8: =IFERROR(N8/VLOOKUP("H2D",Impressoras!$A:$D,4,FALSE),"") -> 0 | R8: =IFERROR(1-(N8/VLOOKUP("H2D",Impressoras!$A:$D,4,FALSE)),"") -> 1
A9: =IF(DATE(YEAR(MIN(Produtos!$A:$A)),MONTH(MIN(Produtos!$A:$A))+ROW()-ROW($A$6),1)>DATE(YEAR(MAX(Produtos!$A:$A)),MONTH(MAX(Produtos!$A:$A)),1),"",DATE(YEAR(MIN(Produtos!$A:$A)),MONTH(MIN(Produtos!$A:$A))+ROW()-ROW($A$6),1)) | B9: =SUMIFS(Produtos!$E:$E,Produtos!$A:$A,">="&A9,Produtos!$A:$A,"<"&EOMONTH(A9,0)+1)/1000 -> 0 | C9: =SUMIFS(Produtos!$F:$F,Produtos!$A:$A,">="&A9,Produtos!$A:$A,"<"&EOMONTH(A9,0)+1) -> 0 | D9: =SUMIFS(Produtos!$G:$G,Produtos!$A:$A,">="&A9,Produtos!$A:$A,"<"&EOMONTH(A9,0)+1) -> 0 | E9: =SUMIFS(Produtos!$H:$H,Produtos!$A:$A,">="&A9,Produtos!$A:$A,"<"&EOMONTH(A9,0)+1) -> 0 | F9: =SUMIFS(Produtos!$I:$I,Produtos!$A:$A,">="&A9,Produtos!$A:$A,"<"&EOMONTH(A9,0)+1) -> 0 | G9: =SUMIFS(Produtos!$J:$J,Produtos!$A:$A,">="&A9,Produtos!$A:$A,"<"&EOMONTH(A9,0)+1)+SUMIFS(Produtos!$K:$K,Produtos!$A:$A,">="&A9,Produtos!$A:$A,"<"&EOMONTH(A9,0)+1)+SUMIFS(Produtos!$L:$L,Produtos!$A:$A,">="&A9,Produtos!$A:$A,"<"&EOMONTH(A9,0)+1)+SUMIFS(Produtos!$M:$M,Produtos!$A:$A,">="&A9,Produtos!$A:$A,"<"&EOMONTH(A9,0)+1) -> 0 | H9: =IFERROR(SUMIFS(Produtos!$K:$K,Produtos!$A:$A,">="&$A9,Produtos!$A:$A,"<"&EOMONTH($A9,0)+1),"") -> 0 | I9: =SUMIFS(Produtos!$T:$T,Produtos!$A:$A,">="&A9,Produtos!$A:$A,"<"&EOMONTH(A9,0)+1) -> 0 | J9: =IF(G9=0,"",(I9-G9)/G9) | K9: =SUMIFS(Produtos!$L:$L,Produtos!$C:$C,K$5,Produtos!$A:$A,">="&A9,Produtos!$A:$A,"<"&EOMONTH(A9,0)+1) -> 0 | L9: =SUMIFS(Produtos!$L:$L,Produtos!$C:$C,L$5,Produtos!$A:$A,">="&B9,Produtos!$A:$A,"<"&EOMONTH(B9,0)+1) -> 0 | M9: =IFERROR(SUMIFS(Produtos!$F:$F,Produtos!$C:$C,"A1 Combo",Produtos!$A:$A,">="&$A9,Produtos!$A:$A,"<"&EOMONTH($A9,0)+1)*24,0) -> 0 | N9: =IFERROR(SUMIFS(Produtos!$F:$F,Produtos!$C:$C,"H2D",Produtos!$A:$A,">="&$A9,Produtos!$A:$A,"<"&EOMONTH($A9,0)+1)*24,0) -> 0 | O9: =IFERROR(M9/VLOOKUP("A1 Combo",Impressoras!$A:$D,4,FALSE),"") -> 0 | P9: =IFERROR(1-(M9/VLOOKUP("A1 Combo",Impressoras!$A:$D,4,FALSE)),"") -> 1 | Q9: =IFERROR(N9/VLOOKUP("H2D",Impressoras!$A:$D,4,FALSE),"") -> 0 | R9: =IFERROR(1-(N9/VLOOKUP("H2D",Impressoras!$A:$D,4,FALSE)),"") -> 1
A10: =IF(DATE(YEAR(MIN(Produtos!$A:$A)),MONTH(MIN(Produtos!$A:$A))+ROW()-ROW($A$6),1)>DATE(YEAR(MAX(Produtos!$A:$A)),MONTH(MAX(Produtos!$A:$A)),1),"",DATE(YEAR(MIN(Produtos!$A:$A)),MONTH(MIN(Produtos!$A:$A))+ROW()-ROW($A$6),1)) | B10: =SUMIFS(Produtos!$E:$E,Produtos!$A:$A,">="&A10,Produtos!$A:$A,"<"&EOMONTH(A10,0)+1)/1000 -> 0 | C10: =SUMIFS(Produtos!$F:$F,Produtos!$A:$A,">="&A10,Produtos!$A:$A,"<"&EOMONTH(A10,0)+1) -> 0 | D10: =SUMIFS(Produtos!$G:$G,Produtos!$A:$A,">="&A10,Produtos!$A:$A,"<"&EOMONTH(A10,0)+1) -> 0 | E10: =SUMIFS(Produtos!$H:$H,Produtos!$A:$A,">="&A10,Produtos!$A:$A,"<"&EOMONTH(A10,0)+1) -> 0 | F10: =SUMIFS(Produtos!$I:$I,Produtos!$A:$A,">="&A10,Produtos!$A:$A,"<"&EOMONTH(A10,0)+1) -> 0 | G10: =SUMIFS(Produtos!$J:$J,Produtos!$A:$A,">="&A10,Produtos!$A:$A,"<"&EOMONTH(A10,0)+1)+SUMIFS(Produtos!$K:$K,Produtos!$A:$A,">="&A10,Produtos!$A:$A,"<"&EOMONTH(A10,0)+1)+SUMIFS(Produtos!$L:$L,Produtos!$A:$A,">="&A10,Produtos!$A:$A,"<"&EOMONTH(A10,0)+1)+SUMIFS(Produtos!$M:$M,Produtos!$A:$A,">="&A10,Produtos!$A:$A,"<"&EOMONTH(A10,0)+1) -> 0 | H10: =IFERROR(SUMIFS(Produtos!$K:$K,Produtos!$A:$A,">="&$A10,Produtos!$A:$A,"<"&EOMONTH($A10,0)+1),"") -> 0 | I10: =SUMIFS(Produtos!$T:$T,Produtos!$A:$A,">="&A10,Produtos!$A:$A,"<"&EOMONTH(A10,0)+1) -> 0 | J10: =IF(G10=0,"",(I10-G10)/G10) | K10: =SUMIFS(Produtos!$L:$L,Produtos!$C:$C,K$5,Produtos!$A:$A,">="&A10,Produtos!$A:$A,"<"&EOMONTH(A10,0)+1) -> 0 | L10: =SUMIFS(Produtos!$L:$L,Produtos!$C:$C,L$5,Produtos!$A:$A,">="&B10,Produtos!$A:$A,"<"&EOMONTH(B10,0)+1) -> 0 | M10: =IFERROR(SUMIFS(Produtos!$F:$F,Produtos!$C:$C,"A1 Combo",Produtos!$A:$A,">="&$A10,Produtos!$A:$A,"<"&EOMONTH($A10,0)+1)*24,0) -> 0 | N10: =IFERROR(SUMIFS(Produtos!$F:$F,Produtos!$C:$C,"H2D",Produtos!$A:$A,">="&$A10,Produtos!$A:$A,"<"&EOMONTH($A10,0)+1)*24,0) -> 0 | O10: =IFERROR(M10/VLOOKUP("A1 Combo",Impressoras!$A:$D,4,FALSE),"") -> 0 | P10: =IFERROR(1-(M10/VLOOKUP("A1 Combo",Impressoras!$A:$D,4,FALSE)),"") -> 1 | Q10: =IFERROR(N10/VLOOKUP("H2D",Impressoras!$A:$D,4,FALSE),"") -> 0 | R10: =IFERROR(1-(N10/VLOOKUP("H2D",Impressoras!$A:$D,4,FALSE)),"") -> 1
A11: =IF(DATE(YEAR(MIN(Produtos!$A:$A)),MONTH(MIN(Produtos!$A:$A))+ROW()-ROW($A$6),1)>DATE(YEAR(MAX(Produtos!$A:$A)),MONTH(MAX(Produtos!$A:$A)),1),"",DATE(YEAR(MIN(Produtos!$A:$A)),MONTH(MIN(Produtos!$A:$A))+ROW()-ROW($A$6),1)) | B11: =SUMIFS(Produtos!$E:$E,Produtos!$A:$A,">="&A11,Produtos!$A:$A,"<"&EOMONTH(A11,0)+1)/1000 -> 0 | C11: =SUMIFS(Produtos!$F:$F,Produtos!$A:$A,">="&A11,Produtos!$A:$A,"<"&EOMONTH(A11,0)+1) -> 0 | D11: =SUMIFS(Produtos!$G:$G,Produtos!$A:$A,">="&A11,Produtos!$A:$A,"<"&EOMONTH(A11,0)+1) -> 0 | E11: =SUMIFS(Produtos!$H:$H,Produtos!$A:$A,">="&A11,Produtos!$A:$A,"<"&EOMONTH(A11,0)+1) -> 0 | F11: =SUMIFS(Produtos!$I:$I,Produtos!$A:$A,">="&A11,Produtos!$A:$A,"<"&EOMONTH(A11,0)+1) -> 0 | G11: =SUMIFS(Produtos!$J:$J,Produtos!$A:$A,">="&A11,Produtos!$A:$A,"<"&EOMONTH(A11,0)+1)+SUMIFS(Produtos!$K:$K,Produtos!$A:$A,">="&A11,Produtos!$A:$A,"<"&EOMONTH(A11,0)+1)+SUMIFS(Produtos!$L:$L,Produtos!$A:$A,">="&A11,Produtos!$A:$A,"<"&EOMONTH(A11,0)+1)+SUMIFS(Produtos!$M:$M,Produtos!$A:$A,">="&A11,Produtos!$A:$A,"<"&EOMONTH(A11,0)+1) -> 0 | H11: =IFERROR(SUMIFS(Produtos!$K:$K,Produtos!$A:$A,">="&$A11,Produtos!$A:$A,"<"&EOMONTH($A11,0)+1),"") -> 0 | I11: =SUMIFS(Produtos!$T:$T,Produtos!$A:$A,">="&A11,Produtos!$A:$A,"<"&EOMONTH(A11,0)+1) -> 0 | J11: =IF(G11=0,"",(I11-G11)/G11) | K11: =SUMIFS(Produtos!$L:$L,Produtos!$C:$C,K$5,Produtos!$A:$A,">="&A11,Produtos!$A:$A,"<"&EOMONTH(A11,0)+1) -> 0 | L11: =SUMIFS(Produtos!$L:$L,Produtos!$C:$C,L$5,Produtos!$A:$A,">="&B11,Produtos!$A:$A,"<"&EOMONTH(B11,0)+1) -> 0 | M11: =IFERROR(SUMIFS(Produtos!$F:$F,Produtos!$C:$C,"A1 Combo",Produtos!$A:$A,">="&$A11,Produtos!$A:$A,"<"&EOMONTH($A11,0)+1)*24,0) -> 0 | N11: =IFERROR(SUMIFS(Produtos!$F:$F,Produtos!$C:$C,"H2D",Produtos!$A:$A,">="&$A11,Produtos!$A:$A,"<"&EOMONTH($A11,0)+1)*24,0) -> 0 | O11: =IFERROR(M11/VLOOKUP("A1 Combo",Impressoras!$A:$D,4,FALSE),"") -> 0 | P11: =IFERROR(1-(M11/VLOOKUP("A1 Combo",Impressoras!$A:$D,4,FALSE)),"") -> 1 | Q11: =IFERROR(N11/VLOOKUP("H2D",Impressoras!$A:$D,4,FALSE),"") -> 0 | R11: =IFERROR(1-(N11/VLOOKUP("H2D",Impressoras!$A:$D,4,FALSE)),"") -> 1
A12: =IF(DATE(YEAR(MIN(Produtos!$A:$A)),MONTH(MIN(Produtos!$A:$A))+ROW()-ROW($A$6),1)>DATE(YEAR(MAX(Produtos!$A:$A)),MONTH(MAX(Produtos!$A:$A)),1),"",DATE(YEAR(MIN(Produtos!$A:$A)),MONTH(MIN(Produtos!$A:$A))+ROW()-ROW($A$6),1)) | B12: =SUMIFS(Produtos!$E:$E,Produtos!$A:$A,">="&A12,Produtos!$A:$A,"<"&EOMONTH(A12,0)+1)/1000 -> 0 | C12: =SUMIFS(Produtos!$F:$F,Produtos!$A:$A,">="&A12,Produtos!$A:$A,"<"&EOMONTH(A12,0)+1) -> 0 | D12: =SUMIFS(Produtos!$G:$G,Produtos!$A:$A,">="&A12,Produtos!$A:$A,"<"&EOMONTH(A12,0)+1) -> 0 | E12: =SUMIFS(Produtos!$H:$H,Produtos!$A:$A,">="&A12,Produtos!$A:$A,"<"&EOMONTH(A12,0)+1) -> 0 | F12: =SUMIFS(Produtos!$I:$I,Produtos!$A:$A,">="&A12,Produtos!$A:$A,"<"&EOMONTH(A12,0)+1) -> 0 | G12: =SUMIFS(Produtos!$J:$J,Produtos!$A:$A,">="&A12,Produtos!$A:$A,"<"&EOMONTH(A12,0)+1)+SUMIFS(Produtos!$K:$K,Produtos!$A:$A,">="&A12,Produtos!$A:$A,"<"&EOMONTH(A12,0)+1)+SUMIFS(Produtos!$L:$L,Produtos!$A:$A,">="&A12,Produtos!$A:$A,"<"&EOMONTH(A12,0)+1)+SUMIFS(Produtos!$M:$M,Produtos!$A:$A,">="&A12,Produtos!$A:$A,"<"&EOMONTH(A12,0)+1) -> 0 | H12: =IFERROR(SUMIFS(Produtos!$K:$K,Produtos!$A:$A,">="&$A12,Produtos!$A:$A,"<"&EOMONTH($A12,0)+1),"") -> 0 | I12: =SUMIFS(Produtos!$T:$T,Produtos!$A:$A,">="&A12,Produtos!$A:$A,"<"&EOMONTH(A12,0)+1) -> 0 | J12: =IF(G12=0,"",(I12-G12)/G12) | K12: =SUMIFS(Produtos!$L:$L,Produtos!$C:$C,K$5,Produtos!$A:$A,">="&A12,Produtos!$A:$A,"<"&EOMONTH(A12,0)+1) -> 0 | L12: =SUMIFS(Produtos!$L:$L,Produtos!$C:$C,L$5,Produtos!$A:$A,">="&B12,Produtos!$A:$A,"<"&EOMONTH(B12,0)+1) -> 0 | M12: =IFERROR(SUMIFS(Produtos!$F:$F,Produtos!$C:$C,"A1 Combo",Produtos!$A:$A,">="&$A12,Produtos!$A:$A,"<"&EOMONTH($A12,0)+1)*24,0) -> 0 | N12: =IFERROR(SUMIFS(Produtos!$F:$F,Produtos!$C:$C,"H2D",Produtos!$A:$A,">="&$A12,Produtos!$A:$A,"<"&EOMONTH($A12,0)+1)*24,0) -> 0 | O12: =IFERROR(M12/VLOOKUP("A1 Combo",Impressoras!$A:$D,4,FALSE),"") -> 0 | P12: =IFERROR(1-(M12/VLOOKUP("A1 Combo",Impressoras!$A:$D,4,FALSE)),"") -> 1 | Q12: =IFERROR(N12/VLOOKUP("H2D",Impressoras!$A:$D,4,FALSE),"") -> 0 | R12: =IFERROR(1-(N12/VLOOKUP("H2D",Impressoras!$A:$D,4,FALSE)),"") -> 1
A13: =IF(DATE(YEAR(MIN(Produtos!$A:$A)),MONTH(MIN(Produtos!$A:$A))+ROW()-ROW($A$6),1)>DATE(YEAR(MAX(Produtos!$A:$A)),MONTH(MAX(Produtos!$A:$A)),1),"",DATE(YEAR(MIN(Produtos!$A:$A)),MONTH(MIN(Produtos!$A:$A))+ROW()-ROW($A$6),1)) | B13: =SUMIFS(Produtos!$E:$E,Produtos!$A:$A,">="&A13,Produtos!$A:$A,"<"&EOMONTH(A13,0)+1)/1000 -> 0 | C13: =SUMIFS(Produtos!$F:$F,Produtos!$A:$A,">="&A13,Produtos!$A:$A,"<"&EOMONTH(A13,0)+1) -> 0 | D13: =SUMIFS(Produtos!$G:$G,Produtos!$A:$A,">="&A13,Produtos!$A:$A,"<"&EOMONTH(A13,0)+1) -> 0 | E13: =SUMIFS(Produtos!$H:$H,Produtos!$A:$A,">="&A13,Produtos!$A:$A,"<"&EOMONTH(A13,0)+1) -> 0 | F13: =SUMIFS(Produtos!$I:$I,Produtos!$A:$A,">="&A13,Produtos!$A:$A,"<"&EOMONTH(A13,0)+1) -> 0 | G13: =SUMIFS(Produtos!$J:$J,Produtos!$A:$A,">="&A13,Produtos!$A:$A,"<"&EOMONTH(A13,0)+1)+SUMIFS(Produtos!$K:$K,Produtos!$A:$A,">="&A13,Produtos!$A:$A,"<"&EOMONTH(A13,0)+1)+SUMIFS(Produtos!$L:$L,Produtos!$A:$A,">="&A13,Produtos!$A:$A,"<"&EOMONTH(A13,0)+1)+SUMIFS(Produtos!$M:$M,Produtos!$A:$A,">="&A13,Produtos!$A:$A,"<"&EOMONTH(A13,0)+1) -> 0 | H13: =IFERROR(SUMIFS(Produtos!$K:$K,Produtos!$A:$A,">="&$A13,Produtos!$A:$A,"<"&EOMONTH($A13,0)+1),"") -> 0 | I13: =SUMIFS(Produtos!$T:$T,Produtos!$A:$A,">="&A13,Produtos!$A:$A,"<"&EOMONTH(A13,0)+1) -> 0 | J13: =IF(G13=0,"",(I13-G13)/G13) | K13: =SUMIFS(Produtos!$L:$L,Produtos!$C:$C,K$5,Produtos!$A:$A,">="&A13,Produtos!$A:$A,"<"&EOMONTH(A13,0)+1) -> 0 | L13: =SUMIFS(Produtos!$L:$L,Produtos!$C:$C,L$5,Produtos!$A:$A,">="&B13,Produtos!$A:$A,"<"&EOMONTH(B13,0)+1) -> 0 | M13: =IFERROR(SUMIFS(Produtos!$F:$F,Produtos!$C:$C,"A1 Combo",Produtos!$A:$A,">="&$A13,Produtos!$A:$A,"<"&EOMONTH($A13,0)+1)*24,0) -> 0 | N13: =IFERROR(SUMIFS(Produtos!$F:$F,Produtos!$C:$C,"H2D",Produtos!$A:$A,">="&$A13,Produtos!$A:$A,"<"&EOMONTH($A13,0)+1)*24,0) -> 0 | O13: =IFERROR(M13/VLOOKUP("A1 Combo",Impressoras!$A:$D,4,FALSE),"") -> 0 | P13: =IFERROR(1-(M13/VLOOKUP("A1 Combo",Impressoras!$A:$D,4,FALSE)),"") -> 1 | Q13: =IFERROR(N13/VLOOKUP("H2D",Impressoras!$A:$D,4,FALSE),"") -> 0 | R13: =IFERROR(1-(N13/VLOOKUP("H2D",Impressoras!$A:$D,4,FALSE)),"") -> 1
A14: =IF(DATE(YEAR(MIN(Produtos!$A:$A)),MONTH(MIN(Produtos!$A:$A))+ROW()-ROW($A$6),1)>DATE(YEAR(MAX(Produtos!$A:$A)),MONTH(MAX(Produtos!$A:$A)),1),"",DATE(YEAR(MIN(Produtos!$A:$A)),MONTH(MIN(Produtos!$A:$A))+ROW()-ROW($A$6),1)) | B14: =SUMIFS(Produtos!$E:$E,Produtos!$A:$A,">="&A14,Produtos!$A:$A,"<"&EOMONTH(A14,0)+1)/1000 -> 0 | C14: =SUMIFS(Produtos!$F:$F,Produtos!$A:$A,">="&A14,Produtos!$A:$A,"<"&EOMONTH(A14,0)+1) -> 0 | D14: =SUMIFS(Produtos!$G:$G,Produtos!$A:$A,">="&A14,Produtos!$A:$A,"<"&EOMONTH(A14,0)+1) -> 0 | E14: =SUMIFS(Produtos!$H:$H,Produtos!$A:$A,">="&A14,Produtos!$A:$A,"<"&EOMONTH(A14,0)+1) -> 0 | F14: =SUMIFS(Produtos!$I:$I,Produtos!$A:$A,">="&A14,Produtos!$A:$A,"<"&EOMONTH(A14,0)+1) -> 0 | G14: =SUMIFS(Produtos!$J:$J,Produtos!$A:$A,">="&A14,Produtos!$A:$A,"<"&EOMONTH(A14,0)+1)+SUMIFS(Produtos!$K:$K,Produtos!$A:$A,">="&A14,Produtos!$A:$A,"<"&EOMONTH(A14,0)+1)+SUMIFS(Produtos!$L:$L,Produtos!$A:$A,">="&A14,Produtos!$A:$A,"<"&EOMONTH(A14,0)+1)+SUMIFS(Produtos!$M:$M,Produtos!$A:$A,">="&A14,Produtos!$A:$A,"<"&EOMONTH(A14,0)+1) -> 0 | H14: =IFERROR(SUMIFS(Produtos!$K:$K,Produtos!$A:$A,">="&$A14,Produtos!$A:$A,"<"&EOMONTH($A14,0)+1),"") -> 0 | I14: =SUMIFS(Produtos!$T:$T,Produtos!$A:$A,">="&A14,Produtos!$A:$A,"<"&EOMONTH(A14,0)+1) -> 0 | J14: =IF(G14=0,"",(I14-G14)/G14) | K14: =SUMIFS(Produtos!$L:$L,Produtos!$C:$C,K$5,Produtos!$A:$A,">="&A14,Produtos!$A:$A,"<"&EOMONTH(A14,0)+1) -> 0 | L14: =SUMIFS(Produtos!$L:$L,Produtos!$C:$C,L$5,Produtos!$A:$A,">="&B14,Produtos!$A:$A,"<"&EOMONTH(B14,0)+1) -> 0 | M14: =IFERROR(SUMIFS(Produtos!$F:$F,Produtos!$C:$C,"A1 Combo",Produtos!$A:$A,">="&$A14,Produtos!$A:$A,"<"&EOMONTH($A14,0)+1)*24,0) -> 0 | N14: =IFERROR(SUMIFS(Produtos!$F:$F,Produtos!$C:$C,"H2D",Produtos!$A:$A,">="&$A14,Produtos!$A:$A,"<"&EOMONTH($A14,0)+1)*24,0) -> 0 | O14: =IFERROR(M14/VLOOKUP("A1 Combo",Impressoras!$A:$D,4,FALSE),"") -> 0 | P14: =IFERROR(1-(M14/VLOOKUP("A1 Combo",Impressoras!$A:$D,4,FALSE)),"") -> 1 | Q14: =IFERROR(N14/VLOOKUP("H2D",Impressoras!$A:$D,4,FALSE),"") -> 0 | R14: =IFERROR(1-(N14/VLOOKUP("H2D",Impressoras!$A:$D,4,FALSE)),"") -> 1
A15: =IF(DATE(YEAR(MIN(Produtos!$A:$A)),MONTH(MIN(Produtos!$A:$A))+ROW()-ROW($A$6),1)>DATE(YEAR(MAX(Produtos!$A:$A)),MONTH(MAX(Produtos!$A:$A)),1),"",DATE(YEAR(MIN(Produtos!$A:$A)),MONTH(MIN(Produtos!$A:$A))+ROW()-ROW($A$6),1)) | B15: =SUMIFS(Produtos!$E:$E,Produtos!$A:$A,">="&A15,Produtos!$A:$A,"<"&EOMONTH(A15,0)+1)/1000 -> 0 | C15: =SUMIFS(Produtos!$F:$F,Produtos!$A:$A,">="&A15,Produtos!$A:$A,"<"&EOMONTH(A15,0)+1) -> 0 | D15: =SUMIFS(Produtos!$G:$G,Produtos!$A:$A,">="&A15,Produtos!$A:$A,"<"&EOMONTH(A15,0)+1) -> 0 | E15: =SUMIFS(Produtos!$H:$H,Produtos!$A:$A,">="&A15,Produtos!$A:$A,"<"&EOMONTH(A15,0)+1) -> 0 | F15: =SUMIFS(Produtos!$I:$I,Produtos!$A:$A,">="&A15,Produtos!$A:$A,"<"&EOMONTH(A15,0)+1) -> 0 | G15: =SUMIFS(Produtos!$J:$J,Produtos!$A:$A,">="&A15,Produtos!$A:$A,"<"&EOMONTH(A15,0)+1)+SUMIFS(Produtos!$K:$K,Produtos!$A:$A,">="&A15,Produtos!$A:$A,"<"&EOMONTH(A15,0)+1)+SUMIFS(Produtos!$L:$L,Produtos!$A:$A,">="&A15,Produtos!$A:$A,"<"&EOMONTH(A15,0)+1)+SUMIFS(Produtos!$M:$M,Produtos!$A:$A,">="&A15,Produtos!$A:$A,"<"&EOMONTH(A15,0)+1) -> 0 | H15: =IFERROR(SUMIFS(Produtos!$K:$K,Produtos!$A:$A,">="&$A15,Produtos!$A:$A,"<"&EOMONTH($A15,0)+1),"") -> 0 | I15: =SUMIFS(Produtos!$T:$T,Produtos!$A:$A,">="&A15,Produtos!$A:$A,"<"&EOMONTH(A15,0)+1) -> 0 | J15: =IF(G15=0,"",(I15-G15)/G15) | K15: =SUMIFS(Produtos!$L:$L,Produtos!$C:$C,K$5,Produtos!$A:$A,">="&A15,Produtos!$A:$A,"<"&EOMONTH(A15,0)+1) -> 0 | L15: =SUMIFS(Produtos!$L:$L,Produtos!$C:$C,L$5,Produtos!$A:$A,">="&B15,Produtos!$A:$A,"<"&EOMONTH(B15,0)+1) -> 0 | M15: =IFERROR(SUMIFS(Produtos!$F:$F,Produtos!$C:$C,"A1 Combo",Produtos!$A:$A,">="&$A15,Produtos!$A:$A,"<"&EOMONTH($A15,0)+1)*24,0) -> 0 | N15: =IFERROR(SUMIFS(Produtos!$F:$F,Produtos!$C:$C,"H2D",Produtos!$A:$A,">="&$A15,Produtos!$A:$A,"<"&EOMONTH($A15,0)+1)*24,0) -> 0 | O15: =IFERROR(M15/VLOOKUP("A1 Combo",Impressoras!$A:$D,4,FALSE),"") -> 0 | P15: =IFERROR(1-(M15/VLOOKUP("A1 Combo",Impressoras!$A:$D,4,FALSE)),"") -> 1 | Q15: =IFERROR(N15/VLOOKUP("H2D",Impressoras!$A:$D,4,FALSE),"") -> 0 | R15: =IFERROR(1-(N15/VLOOKUP("H2D",Impressoras!$A:$D,4,FALSE)),"") -> 1
A16: =IF(DATE(YEAR(MIN(Produtos!$A:$A)),MONTH(MIN(Produtos!$A:$A))+ROW()-ROW($A$6),1)>DATE(YEAR(MAX(Produtos!$A:$A)),MONTH(MAX(Produtos!$A:$A)),1),"",DATE(YEAR(MIN(Produtos!$A:$A)),MONTH(MIN(Produtos!$A:$A))+ROW()-ROW($A$6),1)) | B16: =SUMIFS(Produtos!$E:$E,Produtos!$A:$A,">="&A16,Produtos!$A:$A,"<"&EOMONTH(A16,0)+1)/1000 -> 0 | C16: =SUMIFS(Produtos!$F:$F,Produtos!$A:$A,">="&A16,Produtos!$A:$A,"<"&EOMONTH(A16,0)+1) -> 0 | D16: =SUMIFS(Produtos!$G:$G,Produtos!$A:$A,">="&A16,Produtos!$A:$A,"<"&EOMONTH(A16,0)+1) -> 0 | E16: =SUMIFS(Produtos!$H:$H,Produtos!$A:$A,">="&A16,Produtos!$A:$A,"<"&EOMONTH(A16,0)+1) -> 0 | F16: =SUMIFS(Produtos!$I:$I,Produtos!$A:$A,">="&A16,Produtos!$A:$A,"<"&EOMONTH(A16,0)+1) -> 0 | G16: =SUMIFS(Produtos!$J:$J,Produtos!$A:$A,">="&A16,Produtos!$A:$A,"<"&EOMONTH(A16,0)+1)+SUMIFS(Produtos!$K:$K,Produtos!$A:$A,">="&A16,Produtos!$A:$A,"<"&EOMONTH(A16,0)+1)+SUMIFS(Produtos!$L:$L,Produtos!$A:$A,">="&A16,Produtos!$A:$A,"<"&EOMONTH(A16,0)+1)+SUMIFS(Produtos!$M:$M,Produtos!$A:$A,">="&A16,Produtos!$A:$A,"<"&EOMONTH(A16,0)+1) -> 0 | H16: =IFERROR(SUMIFS(Produtos!$K:$K,Produtos!$A:$A,">="&$A16,Produtos!$A:$A,"<"&EOMONTH($A16,0)+1),"") -> 0 | I16: =SUMIFS(Produtos!$T:$T,Produtos!$A:$A,">="&A16,Produtos!$A:$A,"<"&EOMONTH(A16,0)+1) -> 0 | J16: =IF(G16=0,"",(I16-G16)/G16) | K16: =SUMIFS(Produtos!$L:$L,Produtos!$C:$C,K$5,Produtos!$A:$A,">="&A16,Produtos!$A:$A,"<"&EOMONTH(A16,0)+1) -> 0 | L16: =SUMIFS(Produtos!$L:$L,Produtos!$C:$C,L$5,Produtos!$A:$A,">="&B16,Produtos!$A:$A,"<"&EOMONTH(B16,0)+1) -> 0 | M16: =IFERROR(SUMIFS(Produtos!$F:$F,Produtos!$C:$C,"A1 Combo",Produtos!$A:$A,">="&$A16,Produtos!$A:$A,"<"&EOMONTH($A16,0)+1)*24,0) -> 0 | N16: =IFERROR(SUMIFS(Produtos!$F:$F,Produtos!$C:$C,"H2D",Produtos!$A:$A,">="&$A16,Produtos!$A:$A,"<"&EOMONTH($A16,0)+1)*24,0) -> 0 | O16: =IFERROR(M16/VLOOKUP("A1 Combo",Impressoras!$A:$D,4,FALSE),"") -> 0 | P16: =IFERROR(1-(M16/VLOOKUP("A1 Combo",Impressoras!$A:$D,4,FALSE)),"") -> 1 | Q16: =IFERROR(N16/VLOOKUP("H2D",Impressoras!$A:$D,4,FALSE),"") -> 0 | R16: =IFERROR(1-(N16/VLOOKUP("H2D",Impressoras!$A:$D,4,FALSE)),"") -> 1
A17: =IF(DATE(YEAR(MIN(Produtos!$A:$A)),MONTH(MIN(Produtos!$A:$A))+ROW()-ROW($A$6),1)>DATE(YEAR(MAX(Produtos!$A:$A)),MONTH(MAX(Produtos!$A:$A)),1),"",DATE(YEAR(MIN(Produtos!$A:$A)),MONTH(MIN(Produtos!$A:$A))+ROW()-ROW($A$6),1)) | B17: =SUMIFS(Produtos!$E:$E,Produtos!$A:$A,">="&A17,Produtos!$A:$A,"<"&EOMONTH(A17,0)+1)/1000 -> 0 | C17: =SUMIFS(Produtos!$F:$F,Produtos!$A:$A,">="&A17,Produtos!$A:$A,"<"&EOMONTH(A17,0)+1) -> 0 | D17: =SUMIFS(Produtos!$G:$G,Produtos!$A:$A,">="&A17,Produtos!$A:$A,"<"&EOMONTH(A17,0)+1) -> 0 | E17: =SUMIFS(Produtos!$H:$H,Produtos!$A:$A,">="&A17,Produtos!$A:$A,"<"&EOMONTH(A17,0)+1) -> 0 | F17: =SUMIFS(Produtos!$I:$I,Produtos!$A:$A,">="&A17,Produtos!$A:$A,"<"&EOMONTH(A17,0)+1) -> 0 | G17: =SUMIFS(Produtos!$J:$J,Produtos!$A:$A,">="&A17,Produtos!$A:$A,"<"&EOMONTH(A17,0)+1)+SUMIFS(Produtos!$K:$K,Produtos!$A:$A,">="&A17,Produtos!$A:$A,"<"&EOMONTH(A17,0)+1)+SUMIFS(Produtos!$L:$L,Produtos!$A:$A,">="&A17,Produtos!$A:$A,"<"&EOMONTH(A17,0)+1)+SUMIFS(Produtos!$M:$M,Produtos!$A:$A,">="&A17,Produtos!$A:$A,"<"&EOMONTH(A17,0)+1) -> 0 | H17: =IFERROR(SUMIFS(Produtos!$K:$K,Produtos!$A:$A,">="&$A17,Produtos!$A:$A,"<"&EOMONTH($A17,0)+1),"") -> 0 | I17: =SUMIFS(Produtos!$T:$T,Produtos!$A:$A,">="&A17,Produtos!$A:$A,"<"&EOMONTH(A17,0)+1) -> 0 | J17: =IF(G17=0,"",(I17-G17)/G17) | K17: =SUMIFS(Produtos!$L:$L,Produtos!$C:$C,K$5,Produtos!$A:$A,">="&A17,Produtos!$A:$A,"<"&EOMONTH(A17,0)+1) -> 0 | L17: =SUMIFS(Produtos!$L:$L,Produtos!$C:$C,L$5,Produtos!$A:$A,">="&B17,Produtos!$A:$A,"<"&EOMONTH(B17,0)+1) -> 0 | M17: =IFERROR(SUMIFS(Produtos!$F:$F,Produtos!$C:$C,"A1 Combo",Produtos!$A:$A,">="&$A17,Produtos!$A:$A,"<"&EOMONTH($A17,0)+1)*24,0) -> 0 | N17: =IFERROR(SUMIFS(Produtos!$F:$F,Produtos!$C:$C,"H2D",Produtos!$A:$A,">="&$A17,Produtos!$A:$A,"<"&EOMONTH($A17,0)+1)*24,0) -> 0 | O17: =IFERROR(M17/VLOOKUP("A1 Combo",Impressoras!$A:$D,4,FALSE),"") -> 0 | P17: =IFERROR(1-(M17/VLOOKUP("A1 Combo",Impressoras!$A:$D,4,FALSE)),"") -> 1 | Q17: =IFERROR(N17/VLOOKUP("H2D",Impressoras!$A:$D,4,FALSE),"") -> 0 | R17: =IFERROR(1-(N17/VLOOKUP("H2D",Impressoras!$A:$D,4,FALSE)),"") -> 1
A18: =IF(DATE(YEAR(MIN(Produtos!$A:$A)),MONTH(MIN(Produtos!$A:$A))+ROW()-ROW($A$6),1)>DATE(YEAR(MAX(Produtos!$A:$A)),MONTH(MAX(Produtos!$A:$A)),1),"",DATE(YEAR(MIN(Produtos!$A:$A)),MONTH(MIN(Produtos!$A:$A))+ROW()-ROW($A$6),1)) | B18: =SUMIFS(Produtos!$E:$E,Produtos!$A:$A,">="&A18,Produtos!$A:$A,"<"&EOMONTH(A18,0)+1)/1000 -> 0 | C18: =SUMIFS(Produtos!$F:$F,Produtos!$A:$A,">="&A18,Produtos!$A:$A,"<"&EOMONTH(A18,0)+1) -> 0 | D18: =SUMIFS(Produtos!$G:$G,Produtos!$A:$A,">="&A18,Produtos!$A:$A,"<"&EOMONTH(A18,0)+1) -> 0 | E18: =SUMIFS(Produtos!$H:$H,Produtos!$A:$A,">="&A18,Produtos!$A:$A,"<"&EOMONTH(A18,0)+1) -> 0 | F18: =SUMIFS(Produtos!$I:$I,Produtos!$A:$A,">="&A18,Produtos!$A:$A,"<"&EOMONTH(A18,0)+1) -> 0 | G18: =SUMIFS(Produtos!$J:$J,Produtos!$A:$A,">="&A18,Produtos!$A:$A,"<"&EOMONTH(A18,0)+1)+SUMIFS(Produtos!$K:$K,Produtos!$A:$A,">="&A18,Produtos!$A:$A,"<"&EOMONTH(A18,0)+1)+SUMIFS(Produtos!$L:$L,Produtos!$A:$A,">="&A18,Produtos!$A:$A,"<"&EOMONTH(A18,0)+1)+SUMIFS(Produtos!$M:$M,Produtos!$A:$A,">="&A18,Produtos!$A:$A,"<"&EOMONTH(A18,0)+1) -> 0 | H18: =IFERROR(SUMIFS(Produtos!$K:$K,Produtos!$A:$A,">="&$A18,Produtos!$A:$A,"<"&EOMONTH($A18,0)+1),"") -> 0 | I18: =SUMIFS(Produtos!$T:$T,Produtos!$A:$A,">="&A18,Produtos!$A:$A,"<"&EOMONTH(A18,0)+1) -> 0 | J18: =IF(G18=0,"",(I18-G18)/G18) | K18: =SUMIFS(Produtos!$L:$L,Produtos!$C:$C,K$5,Produtos!$A:$A,">="&A18,Produtos!$A:$A,"<"&EOMONTH(A18,0)+1) -> 0 | L18: =SUMIFS(Produtos!$L:$L,Produtos!$C:$C,L$5,Produtos!$A:$A,">="&B18,Produtos!$A:$A,"<"&EOMONTH(B18,0)+1) -> 0 | M18: =IFERROR(SUMIFS(Produtos!$F:$F,Produtos!$C:$C,"A1 Combo",Produtos!$A:$A,">="&$A18,Produtos!$A:$A,"<"&EOMONTH($A18,0)+1)*24,0) -> 0 | N18: =IFERROR(SUMIFS(Produtos!$F:$F,Produtos!$C:$C,"H2D",Produtos!$A:$A,">="&$A18,Produtos!$A:$A,"<"&EOMONTH($A18,0)+1)*24,0) -> 0 | O18: =IFERROR(M18/VLOOKUP("A1 Combo",Impressoras!$A:$D,4,FALSE),"") -> 0 | P18: =IFERROR(1-(M18/VLOOKUP("A1 Combo",Impressoras!$A:$D,4,FALSE)),"") -> 1 | Q18: =IFERROR(N18/VLOOKUP("H2D",Impressoras!$A:$D,4,FALSE),"") -> 0 | R18: =IFERROR(1-(N18/VLOOKUP("H2D",Impressoras!$A:$D,4,FALSE)),"") -> 1
A19: SubTotal | B19: =SUM(B$2:INDEX(B:B,MATCH(9.99999999999999E+307,A:A))) -> 3.453562 | C19: =SUM(C$2:INDEX(C:C,MATCH(9.99999999999999E+307,A:A))) -> 9.1095833 | D19: =SUM(D$6:INDEX(D:D,MATCH(9.99999999999999E+307,A:A))) -> 0.45833333 | E19: =SUM(E$6:INDEX(E:E,MATCH(9.99999999999999E+307,A:A))) -> 64.2 | F19: =SUM(F$6:INDEX(F:F,MATCH(9.99999999999999E+307,A:A))) -> 0.1 | G19: =SUM(G$2:INDEX(G:G,MATCH(9.99999999999999E+307,A:A))) -> 574.10196 | H19: =SUM(H$6:INDEX(H:H,MATCH(9.99999999999999E+307,A:A))) -> 28.20327 | I19: =SUM(I$2:INDEX(I:I,MATCH(9.99999999999999E+307,A:A))) -> 1259 | J19: =IF(G19=0,"",(I19-G19)/G19) -> 1.1929903 | K19: =SUM(K$2:INDEX(K:K,MATCH(9.99999999999999E+307,A:A))) -> 126.2761 | L19: =SUM(L$6:INDEX(N:N,MATCH(9.99999999999999E+307,A:A))) -> 218.63 | M19: =SUM(M$6:INDEX(M:M,MATCH(9.99999999999999E+307,A:A))) -> 218.63 | N19: =SUM(N$6:INDEX(N:N,MATCH(9.99999999999999E+307,A:A))) -> 0 | O19: =IFERROR(M19/VLOOKUP("A1 Combo",Impressoras!$A:$D,4,FALSE),"") -> 0.021863 | P19: =IFERROR(1-(M19/VLOOKUP("A1 Combo",Impressoras!$A:$D,4,FALSE)),"") -> 0.978137 | Q19: =IFERROR(N19/VLOOKUP("H2D",Impressoras!$A:$D,4,FALSE),"") -> 0 | R19: =IFERROR(1-(N19/VLOOKUP("H2D",Impressoras!$A:$D,4,FALSE)),"") -> 1

Sheet Cadastro de Produtos
B5: Código | C5: Produto | D5: Tamanho | E5: Peso | F5: Cód. Filamento | G5: Tempo | H5: Cor | I5: Pintado? | J5: Perda Padrão (g)
B6: 1 | C6: Chaveiro Glock 17 | D6: 5 x 7cm | E6: 5.55 | F6: 8 | G6: 0.031898148 | H6: Azul | I6: Não | J6: 0.1 | P6: Filamentos
B7: 2 | C7: Chaveiro Glock 17 | D7: 5 x 7cm | E7: 5.55 | F7: 9 | G7: 0.031898148 | H7: Preto | I7: Não
B8: 3 | C8: Chaveiro Glock 17 | D8: 5 x 7cm | E8: 5.55 | F8: 7 | G8: 0.031898148 | H8: Branco | I8: Não | N8: Código | O8: Marca | P8: Tipo | Q8: Cor | R8: Peso(g) | S8: Valor
B9: 4 | C9: Chaveiro Glock 17 | D9: 5 x 7cm | E9: 5.55 | F9: 7 | G9: 0.031898148 | H9: Rosa | I9: Sim | N9: 1 | O9: Bambu Lab | P9: PLA | Q9: Branco | R9: 1000 | S9: 82.9
B10: 5 | C10: Chaveiro Glock 17 | D10: 5 x 7cm | E10: 5.55 | F10: 11 | G10: 0.031898148 | H10: Cinza | I10: Não | N10: 2 | O10: Bambu Lab | P10: PLA | Q10: Preto | R10: 1000 | S10: 82.9
B11: 6 | C11: Chaveiro Glock 17 | D11: 5 x 7cm | E11: 5.55 | F11: 13 | G11: 0.031898148 | H11: Verde | I11: Não | N11: 3 | O11: Bambu Lab | P11: Silk+ | Q11: Azul | R11: 1000 | S11: 85.9
B12: 7 | C12: Chaveiro Glock 17 | D12: 5 x 7cm | E12: 5.55 | F12: 14 | G12: 0.031898148 | H12: Bege | I12: Não | N12: 4 | O12: Bambu Lab | P12: Silk+ | Q12: Dourado | R12: 1000 | S12: 85.9
B13: 8 | C13: Chaveiro Glock 17 | D13: 5 x 7cm | E13: 5.55 | F13: 12 | G13: 0.031898148 | H13: Vermelho | I13: Não | N13: 5 | O13: Bambu Lab | P13: PETG | Q13: Branco | R13: 1000 | S13: 88.3
